Workbook

Sheet Vitality Normative Data
A1: VO2 Max Male | I1: VO2 Max Female | R1: FEV1
A2: Age Group | B2: 10th (Poor) | C2: 25th (Fair) | D2: 50th (Average) | E2: 75th (Good) | F2: 90th (Excellent) | G2: 95th (Superior) | I2: Age Group | J2: 10th (Poor) | K2: 25th (Fair) | L2: 50th (Average) | M2: 75th (Good) | N2: 90th (Excellent) | O2: 95th (Superior) | R2: Height (inches) | S2: Height (cm) | T2: Peak Male FEV1 (Liters) | U2: Peak Female FEV1 (Liters)
A3: 20-29 | B3: 33 | C3: 40.2 | D3: 48 | E3: 56.5 | F3: 64.1 | G3: 69.4 | I3: 20-29 | J3: 23.6 | K3: 28.9 | L3: 37.6 | M3: 44.5 | N3: 51.5 | O3: 55.4 | Q3: 5 foot | R3: 60 | S3: 152 | T3: 3.25 | U3: 2.55
A4: 30-39 | B4: 29.5 | C4: 35.5 | D4: 43.4 | E4: 52.5 | F4: 58.7 | G4: 64.4 | I4: 30-39 | J4: 21.8 | K4: 26.5 | L4: 34.7 | M4: 41 | N4: 47 | O4: 50.8 | R4: 61 | S4: 155 | T4: 3.35 | U4: 2.65
A5: 40-49 | B5: 25.6 | C5: 32.1 | D5: 39.5 | E5: 47.4 | F5: 54.5 | G5: 59.9 | I5: 40-49 | J5: 19 | K5: 24.1 | L5: 30.6 | M5: 36.7 | N5: 42.1 | O5: 46.1 | R5: 62 | S5: 157 | T5: 3.45 | U5: 2.7
A6: 50-59 | B6: 23.3 | C6: 28.6 | D6: 34.5 | E6: 41.5 | F6: 48 | G6: 52.8 | I6: 50-59 | J6: 17 | K6: 21.3 | L6: 26.6 | M6: 31.9 | N6: 36.4 | O6: 39.5 | R6: 63 | S6: 160 | T6: 3.55 | U6: 2.8
A7: 60-69 | B7: 19.3 | C7: 24.3 | D7: 30.2 | E7: 36.3 | F7: 42.1 | G7: 46.4 | I7: 60-69 | J7: 14.7 | K7: 18.2 | L7: 22.8 | M7: 27.2 | N7: 31.3 | O7: 34.6 | R7: 64 | S7: 163 | T7: 3.7 | U7: 2.9
A8: 70-79 | B8: 16.5 | C8: 20.2 | D8: 25.2 | E8: 30.5 | F8: 36.3 | G8: 41.2 | I8: 70-79 | J8: 13 | K8: 16.1 | L8: 20.4 | M8: 24 | N8: 27.7 | O8: 30.7 | R8: 65 | S8: 165 | T8: 3.8 | U8: 3
R9: 66 | S9: 168 | T9: 3.95 | U9: 3.05
R10: 67 | S10: 170 | T10: 4.05 | U10: 3.15
R11: 68 | S11: 173 | T11: 4.2 | U11: 3.25
R12: 69 | S12: 175 | T12: 4.3 | U12: 3.35
R13: 70 | S13: 178 | T13: 4.45 | U13: 3.45
R14: 71 | S14: 180 | T14: 4.55 | U14: 3.5
C15: VO2 Max Taken from the Cooper Institue for Aerobics Research Dallas TX | Q15: 6 foot | R15: 72 | S15: 183 | T15: 4.7 | U15: 3.6
R16: 73 | S16: 185 | T16: 4.85 | U16: 3.7
R17: 74 | S17: 188 | T17: 5 | U17: 3.8
R18: 75 | S18: 190 | T18: 5.15 | U18: 3.9
R21: You should use a spirometry software package that calculates predicted FEV1 values (and other lung function parameters) based on Global Lung Function Initiative (GLI) 2012 reference equations, inputting the individual's age, sex, height, and ethnicity

Sheet Strength_Normative_Data
A1: Grip Strength | J1: Vertical Jump | O1: Sit to Stand
A2: Age | B2: Male Grip (kg) | C2: Female Grip (kg) | J2: Age | K2: Male Jump (cm) | L2: Female Jump (cm) | O2: Age | P2: Male Power (W/kg) | Q2: Female Power (W/kg)
A3: 20 | B3: 48 | C3: 29 | J3: 20 | K3: 53 | L3: 35 | O3: 20 | P3: 4.3 | Q3: 3.2
A4: 25 | B4: 50 | C4: 30 | J4: 25 | K4: 51 | L4: 33.5 | O4: 25 | P4: 4.1 | Q4: 3.1
A5: 30 | B5: 51 | C5: 31 | J5: 30 | K5: 49 | L5: 32 | O5: 30 | P5: 3.9 | Q5: 3
A6: 35 | B6: 50 | C6: 31 | J6: 35 | K6: 46.5 | L6: 30 | O6: 35 | P6: 3.7 | Q6: 2.85
A7: 40 | B7: 49 | C7: 30 | J7: 40 | K7: 44 | L7: 28 | O7: 40 | P7: 3.5 | Q7: 2.7
A8: 45 | B8: 47 | C8: 29 | J8: 45 | K8: 41.5 | L8: 26 | O8: 45 | P8: 3.3 | Q8: 2.55
A9: 50 | B9: 46 | C9: 28 | J9: 50 | K9: 39 | L9: 24 | O9: 50 | P9: 3.1 | Q9: 2.4
A10: 55 | B10: 44 | C10: 27 | J10: 55 | K10: 35.5 | L10: 21.5 | O10: 55 | P10: 2.9 | Q10: 2.25
A11: 60 | B11: 42 | C11: 25 | J11: 60 | K11: 32 | L11: 19 | O11: 60 | P11: 2.7 | Q11: 2.1
A12: 65 | B12: 39 | C12: 23 | J12: 65 | K12: 28.5 | L12: 16.5 | O12: 65 | P12: 2.5 | Q12: 1.95
A13: 70 | B13: 36 | C13: 21 | J13: 70 | K13: 25 | L13: 14 | O13: 70 | P13: 2.3 | Q13: 1.8
A14: 75 | B14: 33 | C14: 19 | J14: 75 | K14: 21.5 | L14: 12 | O14: 75 | P14: 2.1 | Q14: 1.65
A15: 80 | B15: 30 | C15: 17 | J15: 80 | K15: 18 | L15: 10 | O15: 80 | P15: 1.9 | Q15: 1.5
A16: 85 | B16: 26 | C16: 14 | O16: 85 | P16: 1.7 | Q16: 1.35
O17: 90 | P17: 1.5 | Q17: 1.2
A18: Source: https://journals.plos.org/plosone/article?id=10.1371/journal.pone.0113637 | J18: https://go.gale.com/ps/i.do?id=GALE%7CA649711026&sid=googleScholar&v=2.1&it=r&linkaccess=abs&issn=08406529&p=AONE&sw=w&userGroupName=anon%7Eda6c86b0&aty=open-web-entry | O18: https://www.nature.com/articles/s41598-020-73395-4
J19: linked article references canadian health measures suvery which is where normative data originates from | O19: Derived from Toledo study for healthy aging in spain

Sheet Mobility_Normative_Data
A1: Gait Speed | E1: TUG | I1: Single Leg Stance | M1: Sit and Reach
A2: Age | B2: Male (m/s) | C2: Female (m/s) | E2: Age | F2: Male (sec) | G2: Female (sec) | I2: Age | J2: Male (sec) | K2: Female (sec) | M2: Age | N2: Male (cm) | O2: Female (cm)
A3: 20 | B3: 1.36 | C3: 1.34 | E3: 18 | F3: 3 | G3: 3 | I3: 20 | J3: 45 | K3: 45 | M3: 20 | N3: 39 | O3: 42
A4: 25 | B4: 1.36 | C4: 1.34 | E4: 20 | F4: 5 | G4: 5.5 | I4: 25 | J4: 44 | K4: 44 | M4: 25 | N4: 38 | O4: 41
A5: 30 | B5: 1.43 | C5: 1.34 | E5: 25 | F5: 5.2 | G5: 5.8 | I5: 30 | J5: 43 | K5: 43 | M5: 30 | N5: 37 | O5: 40
A6: 35 | B6: 1.43 | C6: 1.34 | E6: 30 | F6: 5.5 | G6: 6 | I6: 35 | J6: 41 | K6: 41 | M6: 35 | N6: 36 | O6: 38
A7: 40 | B7: 1.43 | C7: 1.39 | E7: 35 | F7: 5.8 | G7: 6.2 | I7: 40 | J7: 39 | K7: 39 | M7: 40 | N7: 34 | O7: 37
A8: 45 | B8: 1.43 | C8: 1.39 | E8: 40 | F8: 6 | G8: 6.5 | I8: 45 | J8: 37 | K8: 37 | M8: 45 | N8: 32.5 | O8: 35.5
A9: 50 | B9: 1.43 | C9: 1.31 | E9: 45 | F9: 6.5 | G9: 7 | I9: 50 | J9: 35 | K9: 35 | M9: 50 | N9: 31 | O9: 34
A10: 55 | B10: 1.43 | C10: 1.31 | E10: 50 | F10: 7 | G10: 7.5 | I10: 55 | J10: 33 | K10: 32 | M10: 55 | N10: 29.5 | O10: 32.5
A11: 60 | B11: 1.33 | C11: 1.24 | E11: 55 | F11: 7.5 | G11: 8 | I11: 60 | J11: 30 | K11: 29 | M11: 60 | N11: 28 | O11: 31
A12: 65 | B12: 1.33 | C12: 1.24 | E12: 60 | F12: 8 | G12: 8.5 | I12: 65 | J12: 25 | K12: 22 | M12: 65 | N12: 26.5 | O12: 30
A13: 70 | B13: 1.26 | C13: 1.13 | E13: 65 | F13: 8.5 | G13: 9 | I13: 70 | J13: 20 | K13: 16 | M13: 70 | N13: 25 | O13: 29
A14: 75 | B14: 1.26 | C14: 1.13 | E14: 70 | F14: 9 | G14: 9.5 | I14: 75 | J14: 15 | K14: 11 | M14: 75 | N14: 23.5 | O14: 27.5
A15: 80 | B15: 1.26 | C15: 1.13 | E15: 75 | F15: 9.5 | G15: 10 | I15: 80 | J15: 10 | K15: 7 | M15: 80 | N15: 22 | O15: 26
E16: 80 | F16: 10 | G16: 11 | I16: 85 | J16: 7 | K16: 5 | M16: 85 | N16: 20.5 | O16: 25
E17: 85 | F17: 11 | G17: 12 | I17: 90 | J17: 5 | K17: 3 | M17: 90 | N17: 19 | O17: 24
E18: 90 | F18: 12 | G18: 13
E19: Seems to based off Kearney, P. M., et al. (2013). "Cohort Profile: The Irish Longitudinal Study on Ageing." International Journal of Epidemiology, 40(4), 877-884.
A24: Gait speed | H24: Timed up and go | M24: Single Leg stance | R24: Sit and reach
A25: Age Group | B25: Male (Comfortable) | C25: Male (Maximum) | D25: Female (Comfortable) | E25: Female (Maximum) | H25: Age Group | I25: Mean Time (Seconds) | J25: 95% Confidence Interval | M25: Age Group | N25: Eyes OPEN (Mean ± SD) | O25: Eyes CLOSED (Mean ± SD) | R25: Age Group | S25: Male (cm) | T25: Female (cm)
A26: 20–29 | B26: 1.36 | C26: 2.53 | D26: 1.34 | E26: 2.47 (0.25) | H26: 60–69 | I26: 8.1 | J26: 7.1 – 9.0 | M26: 18–39 | N26: 45.1 (±0.1) | O26: 13.1 (±10.3) | R26: 20–29 | S26: 30 | T26: 33
A27: 30–39 | B27: 1.43 | C27: 2.46 | D27: 1.34 | E27: 2.34 | H27: 70–79 | I27: 9.2 | J27: 8.2 – 10.2 | M27: 40–49 | N27: 42.1 (±9.5) | O27: 13.5 (±8.8) | R27: 30–39 | S27: 28 | T27: 32
A28: 40–49 | B28: 1.43 | C28: 2.46 | D28: 1.39 | E28: 2.12 | H28: 80–99 | I28: 11.3 | J28: 10.0 – 12.7 | M28: 50–59 | N28: 40.9 (±9.9) | O28: 7.9 (±6.6) | R28: 40–49 | S28: 24 | T28: 30
A29: 50–59 | B29: 1.43 | C29: 2.14 | D29: 1.31 | E29: 2.01 | M29: 60–69 | N29: 30.4 (±16.4) | O29: 3.7 (±1.8) | R29: 50–59 | S29: 24 | T29: 30
A30: 60–69 | B30: 1.33 | C30: 1.93 | D30: 1.24 | E30: 1.77 | M30: 70–79 | N30: 16.7 (±15.3) | O30: 2.5 (±1.6) | R30: 60+ | S30: 20 | T30: 27
A31: 70–79 | B31: 1.26 | C31: 2.07 | D31: 1.13 | E31: 1.75 | M31: 80–99 | N31: 10.6 (±12.9) | O31: 1.8 (±1.4)
B33: Bohannon norms Gait speed Link: https://academic.oup.com/ageing/article-abstract/26/1/15/35875?redirectedFrom=fulltext&login=false | H33: The Real "Gold Standard" Data The most cited and reliable source for Timed Up and Go (TUG) norms comes from the meta-analysis by Bohannon (2006). Source: Reference values for the Timed Up and Go Test: A Descriptive Meta-Analysis, published in the Journal of Geriatric Physical Therapy. Here is the Bohannon (2006) data. You will notice it doesn't bother with ages under 60, because the test is clinically irrelevant for younger populations unless they have a specific injury. | M33: Springer, B.A., Marin, R., Cyhan, T., Roberts, H. and Gill, N.W. (2007) ‘Normative values for the unipedal stance test with eyes open and closed’, Journal of Geriatric Physical Therapy, 30(1), pp. 8–15 | R33: American College of Sports Medicine (2021) ACSM’s Guidelines for Exercise Testing and Prescription. 11th edn. Philadelphia: Wolters Kluwer

Sheet Average_20_Year_Old_Man_Pro
A1: Pillar | B1: Metric | D1: 1 | E1: 2 | F1: 3 | G1: 4 | H1: 5 | I1: 6 | J1: 7 | K1: 8 | L1: 9 | M1: 10 | R1: Combined Scores
A2: Vitality | B2: VO2 max (ml/kg/min) | C2: 48 | D2: =C2-(C2/100*D1) -> 47.52 | E2: =D2-(D2/100*E1) -> 46.5696 | F2: =E2-(E2/100*F1) -> 45.172512 | G2: =F2-(F2/100*G1) -> 43.365612 | H2: =G2-(G2/100*H1) -> 41.197331 | I2: =H2-(H2/100*I1) -> 38.725491 | J2: =I2-(I2/100*J1) -> 36.014707 | K2: =J2-(J2/100*K1) -> 33.13353 | ... M2: =L2-(L2/100*M1) -> 27.136361 | Q2: Vitality | R2: =B27+ ((1 -((C2 / 48) * 0.7 )-((C3 / 100) * 0.3 )) * 100) -> 20
A3: Vitality | B3: FEV1 (% predicted) | C3: 100 | D3: =C3-(C3/100*D1) -> 99 | E3: =D3-(D3/100*E1) -> 97.02 | F3: =E3-(E3/100*F1) -> 94.1094 | G3: =F3-(F3/100*G1) -> 90.345024 | H3: =G3-(G3/100*H1) -> 85.827773 | I3: =H3-(H3/100*I1) -> 80.678106 | J3: =I3-(I3/100*J1) -> 75.030639 | K3: =J3-(J3/100*K1) -> 69.028188 | ... M3: =L3-(L3/100*M1) -> 56.534086 | Q3: Strength | R3: =((O4/100*50)+(O5/100*25)+(O6/100*25)) -> 20 | T3: Functional Biological Age
A4: Strength & Power | B4: Grip strength (kg) | C4: 48 | D4: =C4-(C4/100*D1) -> 47.52 | E4: =D4-(D4/100*E1) -> 46.5696 | F4: =E4-(E4/100*F1) -> 45.172512 | G4: =F4-(F4/100*G1) -> 43.365612 | H4: =G4-(G4/100*H1) -> 41.197331 | I4: =H4-(H4/100*I1) -> 38.725491 | J4: =I4-(I4/100*J1) -> 36.014707 | K4: =J4-(J4/100*K1) -> 33.13353 | ... M4: =L4-(L4/100*M1) -> 27.136361 | O4: =IF(B27<30, FORECAST(C4, OFFSET(Strength_Normative_Data!$A$3, MATCH(C4, Strength_Normative_Data!$B$3:$B$5, 1)-1, 0, 2), OFFSET(Strength_Normative_Data!$B$3, MATCH(C4, Strength_Normative_Data!$B$3:$B$5, 1)-1, 0, 2)), FORECAST(C4, OFFSET(Strength_Normative_Data!$A$5, MATCH(C4, Strength_Normative_Data!$B$5:$B$16, -1)-1, 0, 2), OFFSET(Strength_Normative_Data!$B$5, MATCH(C4, Strength_Normative_Data!$B$5:$B$16, -1)-1, 0, 2))) -> 20 | Q4: Metabolic | R4: =B27 - 9*R11 -> 16.296195 | T4: =(R2/100*20)+(R3/100*20)+(R4/100*25)+(R5/100*20)+(R6/100*15) -> 19.074049
A5: Strength & Power | B5: STS Power (W/kg) | C5: 4.3 | M5: =C5-(C5/100*12) -> 3.784 | O5: =FORECAST(C5, OFFSET(Strength_Normative_Data!$O$3, MATCH(C5, Strength_Normative_Data!$P$3:$P$17, -1)-1, 0, 2), OFFSET(Strength_Normative_Data!$P$3, MATCH(C5, Strength_Normative_Data!$P$3:$P$17, -1)-1, 0, 2)) -> 20 | Q5: Functional Mobility | R5: =((O14/100*30)+(O15/100*25)+(O16/100*30)+(O17/100*15)) -> 20
A6: Strength & Power | B6: Vertical jump (cm) | C6: 53 | M6: =C6-(C6/100*12) -> 46.64 | O6: =FORECAST(C6, OFFSET(Strength_Normative_Data!$J$3, MATCH(C6, Strength_Normative_Data!$K$3:$K$16, -1)-1, 0, 2), OFFSET(Strength_Normative_Data!$K$3, MATCH(C6, Strength_Normative_Data!$K$3:$K$16, -1)-1, 0, 2)) -> 20 | Q6: Cognitive | R6: =((O18/100*60)+(O19/100*40)) -> 20
A7: Metabolic Health | B7: Body fat (%) | C7: 22 | M7: =C7+(C7/100*6) -> 23.32
A8: Metabolic Health | B8: Waist to height ratio | C8: 0.48 | M8: =C8+(C8/100*4) -> 0.4992 | O8: =IF(C8<=0.4,0, IF(C8<=0.5,20*(C8-0.4)/0.1, IF(C8<=0.6,20+40*(C8-0.5)/0.1, 60+40*(MIN(C8,0.75)-0.6)/0.15))) -> 16
A9: Metabolic Health | B9: Fasting glucose (mmol/L) | C9: 5.1
A10: Metabolic Health | B10: HbA1c (%) | C10: 5.3 | M10: =C10+(C10/100*5) -> 5.565 | O10: =IF(C10<5.7,10*(C10/5.7), IF(C10<6.5,10+40*(C10-5.7)/0.8, 50+50*(MIN(C10,9)-6.5)/2.5)) -> 9.2982456 | Q10: Metabolic Index | R10: Metabolic Z score
A11: Metabolic Health | B11: HOMA IR | C11: 1.8 | M11: =C11+(C11/100*14) -> 2.052 | O11: =IF(C11<1.6,10*(C11/1.6), IF(C11<3,10+40*(C11-1.6)/1.4, 50+50*(MIN(C11,7)-3)/4)) -> 15.714286 | Q11: =(0.3*P12)+(0.2*O8)+(0.15*O10)+(0.25*O11)+(0.1*O13) -> 14.423308 | R11: =IF(Q11<=10,1.5-0.1*Q11, IF(Q11<=60,0.5-0.02*(Q11-10), -0.5-0.03*(Q11-60))) -> 0.41153383
A12: Metabolic Health | B12: ApoB (g/L) | C12: 0.85 | M12: =C12+(C12/100*6) -> 0.901 | O12: =C12*100 -> 85 | P12: =IF(O12<80,5*(O12/80), IF(O12<100,10+20*(O12-80)/20, IF(O12<130,30+25*(O12-100)/30, IF(O12<160,55+25*(O12-130)/30, IF(O12<200,80+20*(O12-160)/40,100))))) -> 15
A13: Metabolic Health | B13: hsCRP (mg/L) | C13: 1.2 | M13: =C13+(C13/100*18) -> 1.416 | O13: =IF(C13<1,10*(C13/1), IF(C13<3,10+40*(C13-1)/2, 50+50*(MIN(C13,10)-3)/7)) -> 14
A14: Functional Mobility | B14: Gait speed (m/s) | C14: 1.36 | M14: =C14+(C14/100*6) -> 1.4416 | O14: =IFERROR(FORECAST(C14, OFFSET(Mobility_Normative_Data!$A$3, MATCH(C14, Mobility_Normative_Data!$B$3:$B$17, -1)-1, 0, 2), OFFSET(Mobility_Normative_Data!$B$3, MATCH(C14, Mobility_Normative_Data!$B$3:$B$17, -1)-1, 0, 2)), INDEX(Mobility_Normative_Data!$A$3:$A$17, MATCH(C14, Mobility_Normative_Data!$B$3:$B$17, -1))) -> 20
A15: Functional Mobility | B15: Timed Up and Go (sec) | C15: 5 | M15: =C15+(C15/100*10) -> 5.5 | O15: =FORECAST(C15, OFFSET(Mobility_Normative_Data!$E$3, MATCH(C15, Mobility_Normative_Data!$F$3:$F$18, 1)-1, 0, 2), OFFSET(Mobility_Normative_Data!$F$3, MATCH(C15, Mobility_Normative_Data!$F$3:$F$18, 1)-1, 0, 2)) -> 20
A16: Functional Mobility | B16: Single leg stance (sec) | C16: 45 | M16: =C16+(C16/100*20) -> 54 | O16: =FORECAST(C16, OFFSET(Mobility_Normative_Data!$I$3, MATCH(C16, Mobility_Normative_Data!$J$3:$J$17, -1)-1, 0, 2), OFFSET(Mobility_Normative_Data!$J$3, MATCH(C16, Mobility_Normative_Data!$J$3:$J$17, -1)-1, 0, 2)) -> 20
A17: Functional Mobility | B17: Sit and reach (cm) | C17: 39 | M17: =C17+(C17/100*10) -> 42.9 | O17: =FORECAST(C17, OFFSET(Mobility_Normative_Data!$M$3, MATCH(C17, Mobility_Normative_Data!$N$3:$N$17, -1)-1, 0, 2), OFFSET(Mobility_Normative_Data!$N$3, MATCH(C17, Mobility_Normative_Data!$N$3:$N$17, -1)-1, 0, 2)) -> 20
A18: Cognitive Performance | B18: Processing speed (SD) | C18: 0 | M18: =C18 +(-0.2) -> -0.2 | O18: =MAX(18,B27-(C18*25)) -> 20
A19: Cognitive Performance | B19: Working memory (SD) | C19: 0 | M19: =C19+(-0.2) -> -0.2 | O19: =MAX(18,B27-(J1925)) -> 20
A23: Overall Decline predicitons
B25: Present | C25: 10 years time | D25: 20 Years time | E25: Thirty years | F25: 40 years
A26: Sex | B26: Male
A27: Chronological | B27: 20 | C27: =B27+10 -> 30 | D27: =C27+10 -> 40 | E27: =D27+10 -> 50 | F27: =E27+10 -> 60
A28: Vitality | B28: =R2 -> 20 | C28: =B28+(B28/100*11.5) -> 22.3 | D28: =C28+(C28/100*32.2) -> 29.4806 | E28: =D28+(D28/100*32.2) -> 38.973353 | F28: =E28+(E28/100*32.2) -> 51.522773
A29: Strength | B29: =R3 -> 20 | C29: =B29+(B29/100*12.3) -> 22.46 | D29: =C29+(C29/100*30.8) -> 29.37768 | E29: =D29+(D29/100*30.8) -> 38.426005 | F29: =E29+(E29/100*30.8) -> 50.261215
A30: Metabolic | B30: =R4 -> 16.296195 | C30: =B30+(B30/100*5.5) -> 17.192486 | D30: =C30+(C30/100*11) -> 19.08366 | E30: =D30+(D30/100*11) -> 21.182862 | F30: =E30+(E30/100*11) -> 23.512977
A31: Mobility | B31: =R5 -> 20 | C31: =B31+(B31/100*9.9) -> 21.98 | D31: =C31+(C31/100*19.8) -> 26.33204 | E31: =D31+(D31/100*19.8) -> 31.545784 | F31: =E31+(E31/100*19.8) -> 37.791849 | N31: Graphing
A32: Cognitive | B32: =R6 -> 20 | C32: =B32+(B32/100*20) -> 24 | D32: =C32+(C32/100*60) -> 38.4 | E32: =D32+(D32/100*60) -> 61.44 | F32: =E32+(E32/100*60) -> 98.304 | N32: Chronological Age | O32: Vitality Decline of an average 20 Year old Man | Q32: Chronological Age | R32: Strength Decline of an average 20 Year old Man | T32: Chronological Age | U32: Metabolic Decline of an average 20 Year old Man | W32: Chronological Age | X32: Mobility Decline of an average 20 Year old Man | Z32: Chronological Age | AA32: Cognitive Decline of an average 20 Year old Man
N33: =B27 -> 20 | O33: =R2 -> 20 | Q33: =N33 -> 20 | R33: =R3 -> 20 | T33: =N33 -> 20 | U33: =R4 -> 16.296195 | W33: =N33 -> 20 | X33: =R5 -> 20 | Z33: =N33 -> 20 | AA33: =R6 -> 20
N34: =N33+1 -> 21 | O34: =O33+(O33*0.0115) -> 20.23 | Q34: =Q33+1 -> 21 | R34: =R33+(R33*0.0123) -> 20.246 | T34: =T33+1 -> 21 | U34: =U33+(U33*0.0055) -> 16.385825 | W34: =W33+1 -> 21 | X34: =X33+(X33*0.0099) -> 20.198 | Z34: =Z33+1 -> 21 | AA34: =AA33+(AA33*0.02) -> 20.4
N35: =N34+1 -> 22 | O35: =O34+(O34*0.0115) -> 20.462645 | Q35: =Q34+1 -> 22 | R35: =R34+(R34*0.0123) -> 20.495026 | T35: =T34+1 -> 22 | U35: =U34+(U34*0.0055) -> 16.475947 | W35: =W34+1 -> 22 | X35: =X34+(X34*0.0099) -> 20.39796 | Z35: =Z34+1 -> 22 | AA35: =AA34+(AA34*0.02) -> 20.808
A36: Functional Biological Age | N36: =N35+1 -> 23 | O36: =O35+(O35*0.0115) -> 20.697965 | Q36: =Q35+1 -> 23 | R36: =R35+(R35*0.0123) -> 20.747115 | T36: =T35+1 -> 23 | U36: =U35+(U35*0.0055) -> 16.566564 | W36: =W35+1 -> 23 | X36: =X35+(X35*0.0099) -> 20.5999 | Z36: =Z35+1 -> 23 | AA36: =AA35+(AA35*0.02) -> 21.22416
A37: =(B28/100*20)+(B29/100*20)+(B30/100*25)+(B31/100*20)+(B32/100*15) -> 19.074049 | N37: =N36+1 -> 24 | O37: =O36+(O36*0.0115) -> 20.935992 | Q37: =Q36+1 -> 24 | R37: =R36+(R36*0.0123) -> 21.002304 | T37: =T36+1 -> 24 | U37: =U36+(U36*0.0055) -> 16.65768 | W37: =W36+1 -> 24 | X37: =X36+(X36*0.0099) -> 20.803839 | Z37: =Z36+1 -> 24 | AA37: =AA36+(AA36*0.02) -> 21.648643
N38: =N37+1 -> 25 | O38: =O37+(O37*0.0115) -> 21.176756 | Q38: =Q37+1 -> 25 | R38: =R37+(R37*0.0123) -> 21.260632 | T38: =T37+1 -> 25 | U38: =U37+(U37*0.0055) -> 16.749298 | W38: =W37+1 -> 25 | X38: =X37+(X37*0.0099) -> 21.009797 | Z38: =Z37+1 -> 25 | AA38: =AA37+(AA37*0.02) -> 22.081616
N39: =N38+1 -> 26 | O39: =O38+(O38*0.0115) -> 21.420289 | Q39: =Q38+1 -> 26 | R39: =R38+(R38*0.0123) -> 21.522138 | T39: =T38+1 -> 26 | U39: =U38+(U38*0.0055) -> 16.841419 | W39: =W38+1 -> 26 | X39: =X38+(X38*0.0099) -> 21.217794 | Z39: =Z38+1 -> 26 | AA39: =AA38+(AA38*0.02) -> 22.523248
N40: =N39+1 -> 27 | O40: =O39+(O39*0.0115) -> 21.666622 | Q40: =Q39+1 -> 27 | R40: =R39+(R39*0.0123) -> 21.786861 | T40: =T39+1 -> 27 | U40: =U39+(U39*0.0055) -> 16.934047 | W40: =W39+1 -> 27 | X40: =X39+(X39*0.0099) -> 21.42785 | Z40: =Z39+1 -> 27 | AA40: =AA39+(AA39*0.02) -> 22.973713
N41: =N40+1 -> 28 | O41: =O40+(O40*0.0115) -> 21.915788 | Q41: =Q40+1 -> 28 | R41: =R40+(R40*0.0123) -> 22.054839 | T41: =T40+1 -> 28 | U41: =U40+(U40*0.0055) -> 17.027184 | W41: =W40+1 -> 28 | X41: =X40+(X40*0.0099) -> 21.639986 | Z41: =Z40+1 -> 28 | AA41: =AA40+(AA40*0.02) -> 23.433188
B42: Age | C42: Vitality | D42: Age | E42: Strength | F42: Age | G42: Metabolic | H42: Age | I42: Mobility | J42: Age | K42: Cognitive | N42: =N41+1 -> 29 | O42: =O41+(O41*0.0115) -> 22.16782 | Q42: =Q41+1 -> 29 | R42: =R41+(R41*0.0123) -> 22.326113 | T42: =T41+1 -> 29 | U42: =U41+(U41*0.0055) -> 17.120833 | W42: =W41+1 -> 29 | X42: =X41+(X41*0.0099) -> 21.854222 | Z42: =Z41+1 -> 29 | AA42: =AA41+(AA41*0.02) -> 23.901851
B43: =B27 -> 20 | C43: =B28 -> 20 | D43: =B43 -> 20 | E43: =B29 -> 20 | F43: =B27 -> 20 | G43: =B30 -> 16.296195 | H43: =B27 -> 20 | I43: =B31 -> 20 | J43: =B27 -> 20 | K43: =B32 -> 20 | N43: =N42+1 -> 30 | O43: =O42+(O42*0.0115) -> 22.42275 | Q43: =Q42+1 -> 30 | R43: =R42+(R42*0.0123) -> 22.600725 | T43: =T42+1 -> 30 | U43: =U42+(U42*0.0055) -> 17.214998 | W43: =W42+1 -> 30 | X43: =X42+(X42*0.0099) -> 22.070579 | Z43: =Z42+1 -> 30 | AA43: =AA42+(AA42*0.02) -> 24.379888
B44: =C27 -> 30 | C44: =C28 -> 22.3 | D44: =B44 -> 30 | E44: =C29 -> 22.46 | F44: =C27 -> 30 | G44: =C30 -> 17.192486 | H44: =C27 -> 30 | I44: =C31 -> 21.98 | J44: =C27 -> 30 | K44: =C32 -> 24
...

Sheet Average_20_Year_Old_Woman_Pro
A1: Pillar | B1: Metric | D1: 1 | E1: 2 | F1: 3 | G1: 4 | H1: 5 | I1: 6 | J1: 7 | K1: 8 | L1: 9 | M1: 10 | R1: Combined Scores
A2: Vitality | B2: VO2 max (ml/kg/min) | C2: 37.6 | D2: =C2-(C2/100*D1) -> 37.224 | E2: =D2-(D2/100*E1) -> 36.47952 | F2: =E2-(E2/100*F1) -> 35.385134 | G2: =F2-(F2/100*G1) -> 33.969729 | H2: =G2-(G2/100*H1) -> 32.271243 | I2: =H2-(H2/100*I1) -> 30.334968 | J2: =I2-(I2/100*J1) -> 28.21152 | K2: =J2-(J2/100*K1) -> 25.954599 | ... M2: =L2-(L2/100*M1) -> 21.256816 | Q2: Vitality | R2: =B27+ ((1 -((C2 / 37.6) * 0.7 )-((C3 / 100) * 0.3 )) * 100) -> 20
A3: Vitality | B3: FEV1 (% predicted) | C3: 100 | D3: =C3-(C3/100*D1) -> 99 | E3: =D3-(D3/100*E1) -> 97.02 | F3: =E3-(E3/100*F1) -> 94.1094 | G3: =F3-(F3/100*G1) -> 90.345024 | H3: =G3-(G3/100*H1) -> 85.827773 | I3: =H3-(H3/100*I1) -> 80.678106 | J3: =I3-(I3/100*J1) -> 75.030639 | K3: =J3-(J3/100*K1) -> 69.028188 | ... M3: =L3-(L3/100*M1) -> 56.534086 | Q3: Strength | R3: =((O4/100*50)+(O5/100*25)+(O6/100*25)) -> 20 | T3: Functional Biological Age
A4: Strength & Power | B4: Grip strength (kg) | C4: 29 | D4: =C4-(C4/100*D1) -> 28.71 | E4: =D4-(D4/100*E1) -> 28.1358 | F4: =E4-(E4/100*F1) -> 27.291726 | G4: =F4-(F4/100*G1) -> 26.200057 | H4: =G4-(G4/100*H1) -> 24.890054 | I4: =H4-(H4/100*I1) -> 23.396651 | J4: =I4-(I4/100*J1) -> 21.758885 | K4: =J4-(J4/100*K1) -> 20.018174 | ... M4: =L4-(L4/100*M1) -> 16.394885 | O4: 20 | Q4: Metabolic | R4: =B27 - 9*R11 -> 18.547143 | T4: =(R2/100*20)+(R3/100*20)+(R4/100*25)+(R5/100*20)+(R6/100*15) -> 19.636786
A5: Strength & Power | B5: STS Power (W/kg) | C5: 3.2 | M5: =C5-(C5/100*12) -> 2.816 | O5: =FORECAST(C5, OFFSET(Strength_Normative_Data!$O$3, MATCH(C5, Strength_Normative_Data!$Q$3:$Q$17, -1)-1, 0, 2), OFFSET(Strength_Normative_Data!$Q$3, MATCH(C5, Strength_Normative_Data!$Q$3:$Q$17, -1)-1, 0, 2)) -> 20 | Q5: Functional Mobility | R5: =((O14/100*30)+(O15/100*25)+(O16/100*30)+(O17/100*15)) -> 20
A6: Strength & Power | B6: Vertical jump (cm) | C6: 35 | M6: =C6-(C6/100*12) -> 30.8 | O6: =FORECAST(C6, OFFSET(Strength_Normative_Data!$J$3, MATCH(C6, Strength_Normative_Data!$L$3:$L$16, -1)-1, 0, 2), OFFSET(Strength_Normative_Data!$L$3, MATCH(C6, Strength_Normative_Data!$L$3:$L$16, -1)-1, 0, 2)) -> 20 | Q6: Cognitive | R6: =((O18/100*60)+(O19/100*40)) -> 20
A7: Metabolic Health | B7: Body fat (%) | C7: 28 | M7: =C7+(C7/100*6) -> 29.68
A8: Metabolic Health | B8: Waist to height ratio | C8: 0.5 | M8: =C8+(C8/100*4) -> 0.52 | O8: =IF(C8<=0.4,0, IF(C8<=0.5,20*(C8-0.4)/0.1, IF(C8<=0.6,20+40*(C8-0.5)/0.1, 60+40*(MIN(C8,0.75)-0.6)/0.15))) -> 20
A9: Metabolic Health | B9: Fasting glucose (mmol/L) | C9: 5.6
A10: Metabolic Health | B10: HbA1c (%) | C10: 5.7 | M10: =C10+(C10/100*5) -> 5.985 | O10: =IF(C10<5.7,10*(C10/5.7), IF(C10<6.5,10+40*(C10-5.7)/0.8, 50+50*(MIN(C10,9)-6.5)/2.5)) -> 10 | Q10: Metabolic Index | R10: Metabolic Z score
A11: Metabolic Health | B11: HOMA IR | C11: 2.5 | M11: =C11+(C11/100*14) -> 2.85 | O11: =IF(C11<1.6,10*(C11/1.6), IF(C11<3,10+40*(C11-1.6)/1.4, 50+50*(MIN(C11,7)-3)/4)) -> 35.714286 | Q11: =(0.3*P12)+(0.2*O8)+(0.15*O10)+(0.25*O11)+(0.1*O13) -> 26.928571 | R11: =IF(Q11<=10,1.5-0.1*Q11, IF(Q11<=60,0.5-0.02*(Q11-10), -0.5-0.03*(Q11-60))) -> 0.16142857
A12: Metabolic Health | B12: ApoB (g/L) | C12: 1.1 | M12: =C12+(C12/100*6) -> 1.166 | O12: =C12*100 -> 110 | P12: =IF(O12<80,5*(O12/80), IF(O12<100,10+20*(O12-80)/20, IF(O12<130,30+25*(O12-100)/30, IF(O12<160,55+25*(O12-130)/30, IF(O12<200,80+20*(O12-160)/40,100))))) -> 38.333333
A13: Metabolic Health | B13: hsCRP (mg/L) | C13: 1 | M13: =C13+(C13/100*18) -> 1.18 | O13: =IF(C13<1,10*(C13/1), IF(C13<3,10+40*(C13-1)/2, 50+50*(MIN(C13,10)-3)/7)) -> 10
A14: Functional Mobility | B14: Gait speed (m/s) | C14: 1.34 | M14: =C14+(C14/100*6) -> 1.4204 | O14: =IFERROR(FORECAST(C14, OFFSET(Mobility_Normative_Data!$A$3, MATCH(C14, Mobility_Normative_Data!$C$3:$C$17, -1)-1, 0, 2), OFFSET(Mobility_Normative_Data!$C$3, MATCH(C14, Mobility_Normative_Data!$C$3:$C$17, -1)-1, 0, 2)), INDEX(Mobility_Normative_Data!$A$3:$A$17, MATCH(C14, Mobility_Normative_Data!$C$3:$C$17, -1))) -> 20
A15: Functional Mobility | B15: Timed Up and Go (sec) | C15: 5.5 | M15: =C15+(C15/100*10) -> 6.05 | O15: =FORECAST(C15, OFFSET(Mobility_Normative_Data!$E$3, MATCH(C15, Mobility_Normative_Data!$G$3:$G$18, 1)-1, 0, 2), OFFSET(Mobility_Normative_Data!$G$3, MATCH(C15, Mobility_Normative_Data!$G$3:$G$18, 1)-1, 0, 2)) -> 20
A16: Functional Mobility | B16: Single leg stance (sec) | C16: 45 | M16: =C16+(C16/100*20) -> 54 | O16: =FORECAST(C16, OFFSET(Mobility_Normative_Data!$I$3, MATCH(C16, Mobility_Normative_Data!$K$3:$K$17, -1)-1, 0, 2), OFFSET(Mobility_Normative_Data!$K$3, MATCH(C16, Mobility_Normative_Data!$K$3:$K$17, -1)-1, 0, 2)) -> 20
A17: Functional Mobility | B17: Sit and reach (cm) | C17: 42 | M17: =C17+(C17/100*10) -> 46.2 | O17: =FORECAST(C17, OFFSET(Mobility_Normative_Data!$M$3, MATCH(C17, Mobility_Normative_Data!$O$3:$O$17, -1)-1, 0, 2), OFFSET(Mobility_Normative_Data!$O$3, MATCH(C17, Mobility_Normative_Data!$O$3:$O$17, -1)-1, 0, 2)) -> 20
A18: Cognitive Performance | B18: Processing speed (SD) | C18: 0 | M18: =C18 +(-0.2) -> -0.2 | O18: =MAX(18,B27-(C18*25)) -> 20
A19: Cognitive Performance | B19: Working memory (SD) | C19: 0 | M19: =C19+(-0.2) -> -0.2 | O19: =MAX(18,B27-(J1925)) -> 20
A23: Overall Decline predicitons
B25: Present | C25: 10 years time | D25: 20 Years time | E25: Thirty years | F25: 40 years
A26: Sex | B26: Male
A27: Chronological | B27: 20 | C27: =B27+10 -> 30 | D27: =C27+10 -> 40 | E27: =D27+10 -> 50 | F27: =E27+10 -> 60
A28: Vitality | B28: =R2 -> 20 | C28: =B28+(B28/100*11.5) -> 22.3 | D28: =C28+(C28/100*32.2) -> 29.4806 | E28: =D28+(D28/100*32.2) -> 38.973353 | F28: =E28+(E28/100*32.2) -> 51.522773
A29: Strength | B29: =R3 -> 20 | C29: =B29+(B29/100*12.3) -> 22.46 | D29: =C29+(C29/100*30.8) -> 29.37768 | E29: =D29+(D29/100*30.8) -> 38.426005 | F29: =E29+(E29/100*30.8) -> 50.261215
A30: Metabolic | B30: =R4 -> 18.547143 | C30: =B30+(B30/100*5.5) -> 19.567236 | D30: =C30+(C30/100*11) -> 21.719632 | E30: =D30+(D30/100*11) -> 24.108791 | F30: =E30+(E30/100*11) -> 26.760758
A31: Mobility | B31: =R5 -> 20 | C31: =B31+(B31/100*9.9) -> 21.98 | D31: =C31+(C31/100*19.8) -> 26.33204 | E31: =D31+(D31/100*19.8) -> 31.545784 | F31: =E31+(E31/100*19.8) -> 37.791849 | N31: Graphing
A32: Cognitive | B32: =R6 -> 20 | C32: =B32+(B32/100*20) -> 24 | D32: =C32+(C32/100*60) -> 38.4 | E32: =D32+(D32/100*60) -> 61.44 | F32: =E32+(E32/100*60) -> 98.304 | N32: Chronological Age | O32: Vitality Decline of an average 50 Year old Woman | Q32: Chronological Age | R32: Strength Decline of an average 50 Year old Woman | T32: Chronological Age | U32: Metabolic Decline of an average 50 Year old Woman | W32: Chronological Age | X32: Mobility Decline of an average 50 Year old Woman | Z32: Chronological Age | AA32: Cognitive Decline of an average 50 Year old Woman
N33: =B27 -> 20 | O33: =R2 -> 20 | Q33: =N33 -> 20 | R33: =R3 -> 20 | T33: =N33 -> 20 | U33: =R4 -> 18.547143 | W33: =N33 -> 20 | X33: =R5 -> 20 | Z33: =N33 -> 20 | AA33: =R6 -> 20
N34: =N33+1 -> 21 | O34: =O33+(O33*0.0115) -> 20.23 | Q34: =Q33+1 -> 21 | R34: =R33+(R33*0.0123) -> 20.246 | T34: =T33+1 -> 21 | U34: =U33+(U33*0.0055) -> 18.649152 | W34: =W33+1 -> 21 | X34: =X33+(X33*0.0099) -> 20.198 | Z34: =Z33+1 -> 21 | AA34: =AA33+(AA33*0.02) -> 20.4
N35: =N34+1 -> 22 | O35: =O34+(O34*0.0115) -> 20.462645 | Q35: =Q34+1 -> 22 | R35: =R34+(R34*0.0123) -> 20.495026 | T35: =T34+1 -> 22 | U35: =U34+(U34*0.0055) -> 18.751722 | W35: =W34+1 -> 22 | X35: =X34+(X34*0.0099) -> 20.39796 | Z35: =Z34+1 -> 22 | AA35: =AA34+(AA34*0.02) -> 20.808
N36: =N35+1 -> 23 | O36: =O35+(O35*0.0115) -> 20.697965 | Q36: =Q35+1 -> 23 | R36: =R35+(R35*0.0123) -> 20.747115 | T36: =T35+1 -> 23 | U36: =U35+(U35*0.0055) -> 18.854857 | W36: =W35+1 -> 23 | X36: =X35+(X35*0.0099) -> 20.5999 | Z36: =Z35+1 -> 23 | AA36: =AA35+(AA35*0.02) -> 21.22416
N37: =N36+1 -> 24 | O37: =O36+(O36*0.0115) -> 20.935992 | Q37: =Q36+1 -> 24 | R37: =R36+(R36*0.0123) -> 21.002304 | T37: =T36+1 -> 24 | U37: =U36+(U36*0.0055) -> 18.958559 | W37: =W36+1 -> 24 | X37: =X36+(X36*0.0099) -> 20.803839 | Z37: =Z36+1 -> 24 | AA37: =AA36+(AA36*0.02) -> 21.648643
N38: =N37+1 -> 25 | O38: =O37+(O37*0.0115) -> 21.176756 | Q38: =Q37+1 -> 25 | R38: =R37+(R37*0.0123) -> 21.260632 | T38: =T37+1 -> 25 | U38: =U37+(U37*0.0055) -> 19.062831 | W38: =W37+1 -> 25 | X38: =X37+(X37*0.0099) -> 21.009797 | Z38: =Z37+1 -> 25 | AA38: =AA37+(AA37*0.02) -> 22.081616
N39: =N38+1 -> 26 | O39: =O38+(O38*0.0115) -> 21.420289 | Q39: =Q38+1 -> 26 | R39: =R38+(R38*0.0123) -> 21.522138 | T39: =T38+1 -> 26 | U39: =U38+(U38*0.0055) -> 19.167676 | W39: =W38+1 -> 26 | X39: =X38+(X38*0.0099) -> 21.217794 | Z39: =Z38+1 -> 26 | AA39: =AA38+(AA38*0.02) -> 22.523248
N40: =N39+1 -> 27 | O40: =O39+(O39*0.0115) -> 21.666622 | Q40: =Q39+1 -> 27 | R40: =R39+(R39*0.0123) -> 21.786861 | T40: =T39+1 -> 27 | U40: =U39+(U39*0.0055) -> 19.273099 | W40: =W39+1 -> 27 | X40: =X39+(X39*0.0099) -> 21.42785 | Z40: =Z39+1 -> 27 | AA40: =AA39+(AA39*0.02) -> 22.973713
N41: =N40+1 -> 28 | O41: =O40+(O40*0.0115) -> 21.915788 | Q41: =Q40+1 -> 28 | R41: =R40+(R40*0.0123) -> 22.054839 | T41: =T40+1 -> 28 | U41: =U40+(U40*0.0055) -> 19.379101 | W41: =W40+1 -> 28 | X41: =X40+(X40*0.0099) -> 21.639986 | Z41: =Z40+1 -> 28 | AA41: =AA40+(AA40*0.02) -> 23.433188
N42: =N41+1 -> 29 | O42: =O41+(O41*0.0115) -> 22.16782 | Q42: =Q41+1 -> 29 | R42: =R41+(R41*0.0123) -> 22.326113 | T42: =T41+1 -> 29 | U42: =U41+(U41*0.0055) -> 19.485686 | W42: =W41+1 -> 29 | X42: =X41+(X41*0.0099) -> 21.854222 | Z42: =Z41+1 -> 29 | AA42: =AA41+(AA41*0.02) -> 23.901851
N43: =N42+1 -> 30 | O43: =O42+(O42*0.0115) -> 22.42275 | Q43: =Q42+1 -> 30 | R43: =R42+(R42*0.0123) -> 22.600725 | T43: =T42+1 -> 30 | U43: =U42+(U42*0.0055) -> 19.592857 | W43: =W42+1 -> 30 | X43: =X42+(X42*0.0099) -> 22.070579 | Z43: =Z42+1 -> 30 | AA43: =AA42+(AA42*0.02) -> 24.379888

Sheet Average_25_Year_old_Man_Pro 
A1: Pillar | B1: Metric | D1: 1 | E1: 2 | F1: 3 | G1: 4 | H1: 5 | I1: 6 | J1: 7 | K1: 8 | L1: 9 | M1: 10 | R1: Combined Scores
A2: Vitality | B2: VO2 max (ml/kg/min) | C2: 48 | D2: =C2-(C2/100*D1) -> 47.52 | E2: =D2-(D2/100*E1) -> 46.5696 | F2: =E2-(E2/100*F1) -> 45.172512 | G2: =F2-(F2/100*G1) -> 43.365612 | H2: =G2-(G2/100*H1) -> 41.197331 | I2: =H2-(H2/100*I1) -> 38.725491 | J2: =I2-(I2/100*J1) -> 36.014707 | K2: =J2-(J2/100*K1) -> 33.13353 | ... M2: =L2-(L2/100*M1) -> 27.136361 | Q2: Vitality | R2: =B27+ ((1 -((C2 / 48) * 0.7 )-((C3 / 100) * 0.3 )) * 100) -> 25
A3: Vitality | B3: FEV1 (% predicted) | C3: 100 | D3: =C3-(C3/100*D1) -> 99 | E3: =D3-(D3/100*E1) -> 97.02 | F3: =E3-(E3/100*F1) -> 94.1094 | G3: =F3-(F3/100*G1) -> 90.345024 | H3: =G3-(G3/100*H1) -> 85.827773 | I3: =H3-(H3/100*I1) -> 80.678106 | J3: =I3-(I3/100*J1) -> 75.030639 | K3: =J3-(J3/100*K1) -> 69.028188 | ... M3: =L3-(L3/100*M1) -> 56.534086 | Q3: Strength | R3: =((O4/100*50)+(O5/100*25)+(O6/100*25)) -> 25 | T3: Functional Biological Age
A4: Strength & Power | B4: Grip strength (kg) | C4: 50 | D4: =C4-(C4/100*D1) -> 49.5 | E4: =D4-(D4/100*E1) -> 48.51 | F4: =E4-(E4/100*F1) -> 47.0547 | G4: =F4-(F4/100*G1) -> 45.172512 | H4: =G4-(G4/100*H1) -> 42.913886 | I4: =H4-(H4/100*I1) -> 40.339053 | J4: =I4-(I4/100*J1) -> 37.515319 | K4: =J4-(J4/100*K1) -> 34.514094 | ... M4: =L4-(L4/100*M1) -> 28.267043 | O4: =IF(B27<30, FORECAST(C4, OFFSET(Strength_Normative_Data!$A$3, MATCH(C4, Strength_Normative_Data!$B$3:$B$5, 1)-1, 0, 2), OFFSET(Strength_Normative_Data!$B$3, MATCH(C4, Strength_Normative_Data!$B$3:$B$5, 1)-1, 0, 2)), FORECAST(C4, OFFSET(Strength_Normative_Data!$A$5, MATCH(C4, Strength_Normative_Data!$B$5:$B$16, -1)-1, 0, 2), OFFSET(Strength_Normative_Data!$B$5, MATCH(C4, Strength_Normative_Data!$B$5:$B$16, -1)-1, 0, 2))) -> 25 | Q4: Metabolic | R4: =B27 - 9*R11 -> 23.627263 | T4: =(R2/100*20)+(R3/100*20)+(R4/100*25)+(R5/100*20)+(R6/100*15) -> 24.356816
A5: Strength & Power | B5: STS Power (W/kg) | C5: 4.1 | M5: =C5-(C5/100*12) -> 3.608 | O5: =FORECAST(C5, OFFSET(Strength_Normative_Data!$O$3, MATCH(C5, Strength_Normative_Data!$P$3:$P$17, -1)-1, 0, 2), OFFSET(Strength_Normative_Data!$P$3, MATCH(C5, Strength_Normative_Data!$P$3:$P$17, -1)-1, 0, 2)) -> 25 | Q5: Functional Mobility | R5: =((O14/100*30)+(O15/100*25)+(O16/100*30)+(O17/100*15)) -> 23.5
A6: Strength & Power | B6: Vertical jump (cm) | C6: 51 | M6: =C6-(C6/100*12) -> 44.88 | O6: =FORECAST(C6, OFFSET(Strength_Normative_Data!$J$3, MATCH(C6, Strength_Normative_Data!$K$3:$K$16, -1)-1, 0, 2), OFFSET(Strength_Normative_Data!$K$3, MATCH(C6, Strength_Normative_Data!$K$3:$K$16, -1)-1, 0, 2)) -> 25 | Q6: Cognitive | R6: =((O18/100*60)+(O19/100*40)) -> 25
A7: Metabolic Health | B7: Body fat (%) | C7: 22 | M7: =C7+(C7/100*6) -> 23.32
A8: Metabolic Health | B8: Waist to height ratio | C8: 0.55 | M8: =C8+(C8/100*4) -> 0.572 | O8: =IF(C8<=0.4,0, IF(C8<=0.5,20*(C8-0.4)/0.1, IF(C8<=0.6,20+40*(C8-0.5)/0.1, 60+40*(MIN(C8,0.75)-0.6)/0.15))) -> 40
A9: Metabolic Health | B9: Fasting glucose (mmol/L) | C9: 5.1
A10: Metabolic Health | B10: HbA1c (%) | C10: 5.6 | M10: =C10+(C10/100*5) -> 5.88 | O10: =IF(C10<5.7,10*(C10/5.7), IF(C10<6.5,10+40*(C10-5.7)/0.8, 50+50*(MIN(C10,9)-6.5)/2.5)) -> 9.8245614 | Q10: Metabolic Index | R10: Metabolic Z score
A11: Metabolic Health | B11: HOMA IR | C11: 2.3 | M11: =C11+(C11/100*14) -> 2.622 | O11: =IF(C11<1.6,10*(C11/1.6), IF(C11<3,10+40*(C11-1.6)/1.4, 50+50*(MIN(C11,7)-3)/4)) -> 30 | Q11: =(0.3*P12)+(0.2*O8)+(0.15*O10)+(0.25*O11)+(0.1*O13) -> 27.373684 | R11: =IF(Q11<=10,1.5-0.1*Q11, IF(Q11<=60,0.5-0.02*(Q11-10), -0.5-0.03*(Q11-60))) -> 0.15252632
A12: Metabolic Health | B12: ApoB (g/L) | C12: 0.98 | M12: =C12+(C12/100*6) -> 1.0388 | O12: =C12*100 -> 98 | P12: =IF(O12<80,5*(O12/80), IF(O12<100,10+20*(O12-80)/20, IF(O12<130,30+25*(O12-100)/30, IF(O12<160,55+25*(O12-130)/30, IF(O12<200,80+20*(O12-160)/40,100))))) -> 28
A13: Metabolic Health | B13: hsCRP (mg/L) | C13: 1.5 | M13: =C13+(C13/100*18) -> 1.77 | O13: =IF(C13<1,10*(C13/1), IF(C13<3,10+40*(C13-1)/2, 50+50*(MIN(C13,10)-3)/7)) -> 20
A14: Functional Mobility | B14: Gait speed (m/s) | C14: 1.36 | M14: =C14+(C14/100*6) -> 1.4416 | O14: =IFERROR(FORECAST(C14, OFFSET(Mobility_Normative_Data!$A$3, MATCH(C14, Mobility_Normative_Data!$B$3:$B$17, -1)-1, 0, 2), OFFSET(Mobility_Normative_Data!$B$3, MATCH(C14, Mobility_Normative_Data!$B$3:$B$17, -1)-1, 0, 2)), INDEX(Mobility_Normative_Data!$A$3:$A$17, MATCH(C14, Mobility_Normative_Data!$B$3:$B$17, -1))) -> 20
A15: Functional Mobility | B15: Timed Up and Go (sec) | C15: 5.2 | M15: =C15+(C15/100*10) -> 5.72 | O15: =FORECAST(C15, OFFSET(Mobility_Normative_Data!$E$3, MATCH(C15, Mobility_Normative_Data!$F$3:$F$18, 1)-1, 0, 2), OFFSET(Mobility_Normative_Data!$F$3, MATCH(C15, Mobility_Normative_Data!$F$3:$F$18, 1)-1, 0, 2)) -> 25
A16: Functional Mobility | B16: Single leg stance (sec) | C16: 44 | M16: =C16+(C16/100*20) -> 52.8 | O16: =FORECAST(C16, OFFSET(Mobility_Normative_Data!$I$3, MATCH(C16, Mobility_Normative_Data!$J$3:$J$17, -1)-1, 0, 2), OFFSET(Mobility_Normative_Data!$J$3, MATCH(C16, Mobility_Normative_Data!$J$3:$J$17, -1)-1, 0, 2)) -> 25
A17: Functional Mobility | B17: Sit and reach (cm) | C17: 38 | M17: =C17+(C17/100*10) -> 41.8 | O17: =FORECAST(C17, OFFSET(Mobility_Normative_Data!$M$3, MATCH(C17, Mobility_Normative_Data!$N$3:$N$17, -1)-1, 0, 2), OFFSET(Mobility_Normative_Data!$N$3, MATCH(C17, Mobility_Normative_Data!$N$3:$N$17, -1)-1, 0, 2)) -> 25
A18: Cognitive Performance | B18: Processing speed (SD) | C18: 0 | M18: =C18 +(-0.2) -> -0.2 | O18: =MAX(18,B27-(C18*25)) -> 25
A19: Cognitive Performance | B19: Working memory (SD) | C19: 0 | M19: =C19+(-0.2) -> -0.2 | O19: =MAX(18,B27-(J1925)) -> 25
A23: Overall Decline predicitons
B25: Present | C25: 10 years time | D25: 20 Years time | E25: Thirty years | F25: 40 years
A26: Sex | B26: Male
A27: Chronological | B27: 25 | C27: =B27+10 -> 35 | D27: =C27+10 -> 45 | E27: =D27+10 -> 55 | F27: =E27+10 -> 65
A28: Vitality | B28: =R2 -> 25 | C28: =B28+(B28/100*11.5) -> 27.875 | D28: =C28+(C28/100*32.2) -> 36.85075 | E28: =D28+(D28/100*32.2) -> 48.716692 | F28: =E28+(E28/100*32.2) -> 64.403466
A29: Strength | B29: =R3 -> 25 | C29: =B29+(B29/100*12.3) -> 28.075 | D29: =C29+(C29/100*30.8) -> 36.7221 | E29: =D29+(D29/100*30.8) -> 48.032507 | F29: =E29+(E29/100*30.8) -> 62.826519
A30: Metabolic | B30: =R4 -> 23.627263 | C30: =B30+(B30/100*5.5) -> 24.926763 | D30: =C30+(C30/100*11) -> 27.668707 | E30: =D30+(D30/100*11) -> 30.712264 | F30: =E30+(E30/100*11) -> 34.090613
A31: Mobility | B31: =R5 -> 23.5 | C31: =B31+(B31/100*9.9) -> 25.8265 | D31: =C31+(C31/100*19.8) -> 30.940147 | E31: =D31+(D31/100*19.8) -> 37.066296 | F31: =E31+(E31/100*19.8) -> 44.405423 | N31: Graphing
A32: Cognitive | B32: =R6 -> 25 | C32: =B32+(B32/100*20) -> 30 | D32: =C32+(C32/100*60) -> 48 | E32: =D32+(D32/100*60) -> 76.8 | F32: =E32+(E32/100*60) -> 122.88 | N32: Chronological Age | O32: Vitality Decline of an average 20 Year old Man | Q32: Chronological Age | R32: Strength Decline of an average 20 Year old Man | T32: Chronological Age | U32: Metabolic Decline of an average 20 Year old Man | W32: Chronological Age | X32: Mobility Decline of an average 20 Year old Man | Z32: Chronological Age | AA32: Cognitive Decline of an average 20 Year old Man
N33: =B27 -> 25 | O33: =R2 -> 25 | Q33: =N33 -> 25 | R33: =R3 -> 25 | T33: =N33 -> 25 | U33: =R4 -> 23.627263 | W33: =N33 -> 25 | X33: =R5 -> 23.5 | Z33: =N33 -> 25 | AA33: =R6 -> 25
N34: =N33+1 -> 26 | O34: =O33+(O33*0.0115) -> 25.2875 | Q34: =Q33+1 -> 26 | R34: =R33+(R33*0.0123) -> 25.3075 | T34: =T33+1 -> 26 | U34: =U33+(U33*0.0055) -> 23.757213 | W34: =W33+1 -> 26 | X34: =X33+(X33*0.0099) -> 23.73265 | Z34: =Z33+1 -> 26 | AA34: =AA33+(AA33*0.02) -> 25.5
N35: =N34+1 -> 27 | O35: =O34+(O34*0.0115) -> 25.578306 | Q35: =Q34+1 -> 27 | R35: =R34+(R34*0.0123) -> 25.618782 | T35: =T34+1 -> 27 | U35: =U34+(U34*0.0055) -> 23.887878 | W35: =W34+1 -> 27 | X35: =X34+(X34*0.0099) -> 23.967603 | Z35: =Z34+1 -> 27 | AA35: =AA34+(AA34*0.02) -> 26.01
A36: Functional Biological Age | N36: =N35+1 -> 28 | O36: =O35+(O35*0.0115) -> 25.872457 | Q36: =Q35+1 -> 28 | R36: =R35+(R35*0.0123) -> 25.933893 | T36: =T35+1 -> 28 | U36: =U35+(U35*0.0055) -> 24.019261 | W36: =W35+1 -> 28 | X36: =X35+(X35*0.0099) -> 24.204883 | Z36: =Z35+1 -> 28 | AA36: =AA35+(AA35*0.02) -> 26.5302
A37: =(B28/100*20)+(B29/100*20)+(B30/100*25)+(B31/100*20)+(B32/100*15) -> 24.356816 | N37: =N36+1 -> 29 | O37: =O36+(O36*0.0115) -> 26.16999 | Q37: =Q36+1 -> 29 | R37: =R36+(R36*0.0123) -> 26.25288 | T37: =T36+1 -> 29 | U37: =U36+(U36*0.0055) -> 24.151367 | W37: =W36+1 -> 29 | X37: =X36+(X36*0.0099) -> 24.444511 | Z37: =Z36+1 -> 29 | AA37: =AA36+(AA36*0.02) -> 27.060804
N38: =N37+1 -> 30 | O38: =O37+(O37*0.0115) -> 26.470945 | Q38: =Q37+1 -> 30 | R38: =R37+(R37*0.0123) -> 26.575791 | T38: =T37+1 -> 30 | U38: =U37+(U37*0.0055) -> 24.2842 | W38: =W37+1 -> 30 | X38: =X37+(X37*0.0099) -> 24.686512 | Z38: =Z37+1 -> 30 | AA38: =AA37+(AA37*0.02) -> 27.60202
N39: =N38+1 -> 31 | O39: =O38+(O38*0.0115) -> 26.775361 | Q39: =Q38+1 -> 31 | R39: =R38+(R38*0.0123) -> 26.902673 | T39: =T38+1 -> 31 | U39: =U38+(U38*0.0055) -> 24.417763 | W39: =W38+1 -> 31 | X39: =X38+(X38*0.0099) -> 24.930908 | Z39: =Z38+1 -> 31 | AA39: =AA38+(AA38*0.02) -> 28.15406
N40: =N39+1 -> 32 | O40: =O39+(O39*0.0115) -> 27.083277 | Q40: =Q39+1 -> 32 | R40: =R39+(R39*0.0123) -> 27.233576 | T40: =T39+1 -> 32 | U40: =U39+(U39*0.0055) -> 24.55206 | W40: =W39+1 -> 32 | X40: =X39+(X39*0.0099) -> 25.177724 | Z40: =Z39+1 -> 32 | AA40: =AA39+(AA39*0.02) -> 28.717142
N41: =N40+1 -> 33 | O41: =O40+(O40*0.0115) -> 27.394735 | Q41: =Q40+1 -> 33 | R41: =R40+(R40*0.0123) -> 27.568549 | T41: =T40+1 -> 33 | U41: =U40+(U40*0.0055) -> 24.687097 | W41: =W40+1 -> 33 | X41: =X40+(X40*0.0099) -> 25.426983 | Z41: =Z40+1 -> 33 | AA41: =AA40+(AA40*0.02) -> 29.291485
B42: Age | C42: Vitality | D42: Age | E42: Strength | F42: Age | G42: Metabolic | H42: Age | I42: Mobility | J42: Age | K42: Cognitive | N42: =N41+1 -> 34 | O42: =O41+(O41*0.0115) -> 27.709775 | Q42: =Q41+1 -> 34 | R42: =R41+(R41*0.0123) -> 27.907642 | T42: =T41+1 -> 34 | U42: =U41+(U41*0.0055) -> 24.822876 | W42: =W41+1 -> 34 | X42: =X41+(X41*0.0099) -> 25.678711 | Z42: =Z41+1 -> 34 | AA42: =AA41+(AA41*0.02) -> 29.877314
B43: =B27 -> 25 | C43: =B28 -> 25 | D43: =B43 -> 25 | E43: =B29 -> 25 | F43: =B27 -> 25 | G43: =B30 -> 23.627263 | H43: =B27 -> 25 | I43: =B31 -> 23.5 | J43: =B27 -> 25 | K43: =B32 -> 25 | N43: =N42+1 -> 35 | O43: =O42+(O42*0.0115) -> 28.028437 | Q43: =Q42+1 -> 35 | R43: =R42+(R42*0.0123) -> 28.250906 | T43: =T42+1 -> 35 | U43: =U42+(U42*0.0055) -> 24.959402 | W43: =W42+1 -> 35 | X43: =X42+(X42*0.0099) -> 25.93293 | Z43: =Z42+1 -> 35 | AA43: =AA42+(AA42*0.02) -> 30.47486
B44: =C27 -> 35 | C44: =C28 -> 27.875 | D44: =B44 -> 35 | E44: =C29 -> 28.075 | F44: =C27 -> 35 | G44: =C30 -> 24.926763 | H44: =C27 -> 35 | I44: =C31 -> 25.8265 | J44: =C27 -> 35 | K44: =C32 -> 30
...

Sheet Average_25_Year_Old_Woman_P 
A1: Pillar | B1: Metric | D1: 1 | E1: 2 | F1: 3 | G1: 4 | H1: 5 | I1: 6 | J1: 7 | K1: 8 | L1: 9 | M1: 10 | R1: Combined Scores
A2: Vitality | B2: VO2 max (ml/kg/min) | C2: 37.6 | D2: =C2-(C2/100*D1) -> 37.224 | E2: =D2-(D2/100*E1) -> 36.47952 | F2: =E2-(E2/100*F1) -> 35.385134 | G2: =F2-(F2/100*G1) -> 33.969729 | H2: =G2-(G2/100*H1) -> 32.271243 | I2: =H2-(H2/100*I1) -> 30.334968 | J2: =I2-(I2/100*J1) -> 28.21152 | K2: =J2-(J2/100*K1) -> 25.954599 | ... M2: =L2-(L2/100*M1) -> 21.256816 | Q2: Vitality | R2: =B27+ ((1 -((C2 / 37.6) * 0.7 )-((C3 / 100) * 0.3 )) * 100) -> 25
A3: Vitality | B3: FEV1 (% predicted) | C3: 100 | D3: =C3-(C3/100*D1) -> 99 | E3: =D3-(D3/100*E1) -> 97.02 | F3: =E3-(E3/100*F1) -> 94.1094 | G3: =F3-(F3/100*G1) -> 90.345024 | H3: =G3-(G3/100*H1) -> 85.827773 | I3: =H3-(H3/100*I1) -> 80.678106 | J3: =I3-(I3/100*J1) -> 75.030639 | K3: =J3-(J3/100*K1) -> 69.028188 | ... M3: =L3-(L3/100*M1) -> 56.534086 | Q3: Strength | R3: =((O4/100*50)+(O5/100*25)+(O6/100*25)) -> 25 | T3: Functional Biological Age
A4: Strength & Power | B4: Grip strength (kg) | C4: 30 | D4: =C4-(C4/100*D1) -> 29.7 | E4: =D4-(D4/100*E1) -> 29.106 | F4: =E4-(E4/100*F1) -> 28.23282 | G4: =F4-(F4/100*G1) -> 27.103507 | H4: =G4-(G4/100*H1) -> 25.748332 | I4: =H4-(H4/100*I1) -> 24.203432 | J4: =I4-(I4/100*J1) -> 22.509192 | K4: =J4-(J4/100*K1) -> 20.708456 | ... M4: =L4-(L4/100*M1) -> 16.960226 | O4: 25 | Q4: Metabolic | R4: =B27 - 9*R11 -> 23.619143 | T4: =(R2/100*20)+(R3/100*20)+(R4/100*25)+(R5/100*20)+(R6/100*15) -> 24.354786
A5: Strength & Power | B5: STS Power (W/kg) | C5: 3.1 | M5: =C5-(C5/100*12) -> 2.728 | O5: =FORECAST(C5, OFFSET(Strength_Normative_Data!$O$3, MATCH(C5, Strength_Normative_Data!$Q$3:$Q$17, -1)-1, 0, 2), OFFSET(Strength_Normative_Data!$Q$3, MATCH(C5, Strength_Normative_Data!$Q$3:$Q$17, -1)-1, 0, 2)) -> 25 | Q5: Functional Mobility | R5: =((O14/100*30)+(O15/100*25)+(O16/100*30)+(O17/100*15)) -> 23.5
A6: Strength & Power | B6: Vertical jump (cm) | C6: 33.5 | M6: =C6-(C6/100*12) -> 29.48 | O6: =FORECAST(C6, OFFSET(Strength_Normative_Data!$J$3, MATCH(C6, Strength_Normative_Data!$L$3:$L$16, -1)-1, 0, 2), OFFSET(Strength_Normative_Data!$L$3, MATCH(C6, Strength_Normative_Data!$L$3:$L$16, -1)-1, 0, 2)) -> 25 | Q6: Cognitive | R6: =((O18/100*60)+(O19/100*40)) -> 25
A7: Metabolic Health | B7: Body fat (%) | C7: 29 | M7: =C7+(C7/100*6) -> 30.74
A8: Metabolic Health | B8: Waist to height ratio | C8: 0.5 | M8: =C8+(C8/100*4) -> 0.52 | O8: =IF(C8<=0.4,0, IF(C8<=0.5,20*(C8-0.4)/0.1, IF(C8<=0.6,20+40*(C8-0.5)/0.1, 60+40*(MIN(C8,0.75)-0.6)/0.15))) -> 20
A9: Metabolic Health | B9: Fasting glucose (mmol/L) | C9: 4.9
A10: Metabolic Health | B10: HbA1c (%) | C10: 5.7 | M10: =C10+(C10/100*5) -> 5.985 | O10: =IF(C10<5.7,10*(C10/5.7), IF(C10<6.5,10+40*(C10-5.7)/0.8, 50+50*(MIN(C10,9)-6.5)/2.5)) -> 10 | Q10: Metabolic Index | R10: Metabolic Z score
A11: Metabolic Health | B11: HOMA IR | C11: 2.5 | M11: =C11+(C11/100*14) -> 2.85 | O11: =IF(C11<1.6,10*(C11/1.6), IF(C11<3,10+40*(C11-1.6)/1.4, 50+50*(MIN(C11,7)-3)/4)) -> 35.714286 | Q11: =(0.3*P12)+(0.2*O8)+(0.15*O10)+(0.25*O11)+(0.1*O13) -> 27.328571 | R11: =IF(Q11<=10,1.5-0.1*Q11, IF(Q11<=60,0.5-0.02*(Q11-10), -0.5-0.03*(Q11-60))) -> 0.15342857
A12: Metabolic Health | B12: ApoB (g/L) | C12: 1.1 | M12: =C12+(C12/100*6) -> 1.166 | O12: =C12*100 -> 110 | P12: =IF(O12<80,5*(O12/80), IF(O12<100,10+20*(O12-80)/20, IF(O12<130,30+25*(O12-100)/30, IF(O12<160,55+25*(O12-130)/30, IF(O12<200,80+20*(O12-160)/40,100))))) -> 38.333333
A13: Metabolic Health | B13: hsCRP (mg/L) | C13: 1.2 | M13: =C13+(C13/100*18) -> 1.416 | O13: =IF(C13<1,10*(C13/1), IF(C13<3,10+40*(C13-1)/2, 50+50*(MIN(C13,10)-3)/7)) -> 14
A14: Functional Mobility | B14: Gait speed (m/s) | C14: 1.34 | M14: =C14+(C14/100*6) -> 1.4204 | O14: =IFERROR(FORECAST(C14, OFFSET(Mobility_Normative_Data!$A$3, MATCH(C14, Mobility_Normative_Data!$C$3:$C$17, -1)-1, 0, 2), OFFSET(Mobility_Normative_Data!$C$3, MATCH(C14, Mobility_Normative_Data!$C$3:$C$17, -1)-1, 0, 2)), INDEX(Mobility_Normative_Data!$A$3:$A$17, MATCH(C14, Mobility_Normative_Data!$C$3:$C$17, -1))) -> 20
A15: Functional Mobility | B15: Timed Up and Go (sec) | C15: 5.8 | M15: =C15+(C15/100*10) -> 6.38 | O15: =FORECAST(C15, OFFSET(Mobility_Normative_Data!$E$3, MATCH(C15, Mobility_Normative_Data!$G$3:$G$18, 1)-1, 0, 2), OFFSET(Mobility_Normative_Data!$G$3, MATCH(C15, Mobility_Normative_Data!$G$3:$G$18, 1)-1, 0, 2)) -> 25
A16: Functional Mobility | B16: Single leg stance (sec) | C16: 44 | M16: =C16+(C16/100*20) -> 52.8 | O16: =FORECAST(C16, OFFSET(Mobility_Normative_Data!$I$3, MATCH(C16, Mobility_Normative_Data!$K$3:$K$17, -1)-1, 0, 2), OFFSET(Mobility_Normative_Data!$K$3, MATCH(C16, Mobility_Normative_Data!$K$3:$K$17, -1)-1, 0, 2)) -> 25
A17: Functional Mobility | B17: Sit and reach (cm) | C17: 41 | M17: =C17+(C17/100*10) -> 45.1 | O17: =FORECAST(C17, OFFSET(Mobility_Normative_Data!$M$3, MATCH(C17, Mobility_Normative_Data!$O$3:$O$17, -1)-1, 0, 2), OFFSET(Mobility_Normative_Data!$O$3, MATCH(C17, Mobility_Normative_Data!$O$3:$O$17, -1)-1, 0, 2)) -> 25
A18: Cognitive Performance | B18: Processing speed (SD) | C18: 0 | M18: =C18 +(-0.2) -> -0.2 | O18: =MAX(18,B27-(C18*25)) -> 25
A19: Cognitive Performance | B19: Working memory (SD) | C19: 0 | M19: =C19+(-0.2) -> -0.2 | O19: =MAX(18,B27-(J1925)) -> 25
A23: Overall Decline predicitons
B25: Present | C25: 10 years time | D25: 20 Years time | E25: Thirty years | F25: 40 years
A26: Sex | B26: Male
A27: Chronological | B27: 25 | C27: =B27+10 -> 35 | D27: =C27+10 -> 45 | E27: =D27+10 -> 55 | F27: =E27+10 -> 65
A28: Vitality | B28: =R2 -> 25 | C28: =B28+(B28/100*11.5) -> 27.875 | D28: =C28+(C28/100*32.2) -> 36.85075 | E28: =D28+(D28/100*32.2) -> 48.716692 | F28: =E28+(E28/100*32.2) -> 64.403466
A29: Strength | B29: =R3 -> 25 | C29: =B29+(B29/100*12.3) -> 28.075 | D29: =C29+(C29/100*30.8) -> 36.7221 | E29: =D29+(D29/100*30.8) -> 48.032507 | F29: =E29+(E29/100*30.8) -> 62.826519
A30: Metabolic | B30: =R4 -> 23.619143 | C30: =B30+(B30/100*5.5) -> 24.918196 | D30: =C30+(C30/100*11) -> 27.659197 | E30: =D30+(D30/100*11) -> 30.701709 | F30: =E30+(E30/100*11) -> 34.078897
A31: Mobility | B31: =R5 -> 23.5 | C31: =B31+(B31/100*9.9) -> 25.8265 | D31: =C31+(C31/100*19.8) -> 30.940147 | E31: =D31+(D31/100*19.8) -> 37.066296 | F31: =E31+(E31/100*19.8) -> 44.405423 | N31: Graphing
A32: Cognitive | B32: =R6 -> 25 | C32: =B32+(B32/100*20) -> 30 | D32: =C32+(C32/100*60) -> 48 | E32: =D32+(D32/100*60) -> 76.8 | F32: =E32+(E32/100*60) -> 122.88 | N32: Chronological Age | O32: Vitality Decline of an average 50 Year old Woman | Q32: Chronological Age | R32: Strength Decline of an average 50 Year old Woman | T32: Chronological Age | U32: Metabolic Decline of an average 50 Year old Woman | W32: Chronological Age | X32: Mobility Decline of an average 50 Year old Woman | Z32: Chronological Age | AA32: Cognitive Decline of an average 50 Year old Woman
N33: =B27 -> 25 | O33: =R2 -> 25 | Q33: =N33 -> 25 | R33: =R3 -> 25 | T33: =N33 -> 25 | U33: =R4 -> 23.619143 | W33: =N33 -> 25 | X33: =R5 -> 23.5 | Z33: =N33 -> 25 | AA33: =R6 -> 25
N34: =N33+1 -> 26 | O34: =O33+(O33*0.0115) -> 25.2875 | Q34: =Q33+1 -> 26 | R34: =R33+(R33*0.0123) -> 25.3075 | T34: =T33+1 -> 26 | U34: =U33+(U33*0.0055) -> 23.749048 | W34: =W33+1 -> 26 | X34: =X33+(X33*0.0099) -> 23.73265 | Z34: =Z33+1 -> 26 | AA34: =AA33+(AA33*0.02) -> 25.5
N35: =N34+1 -> 27 | O35: =O34+(O34*0.0115) -> 25.578306 | Q35: =Q34+1 -> 27 | R35: =R34+(R34*0.0123) -> 25.618782 | T35: =T34+1 -> 27 | U35: =U34+(U34*0.0055) -> 23.879668 | W35: =W34+1 -> 27 | X35: =X34+(X34*0.0099) -> 23.967603 | Z35: =Z34+1 -> 27 | AA35: =AA34+(AA34*0.02) -> 26.01
N36: =N35+1 -> 28 | O36: =O35+(O35*0.0115) -> 25.872457 | Q36: =Q35+1 -> 28 | R36: =R35+(R35*0.0123) -> 25.933893 | T36: =T35+1 -> 28 | U36: =U35+(U35*0.0055) -> 24.011006 | W36: =W35+1 -> 28 | X36: =X35+(X35*0.0099) -> 24.204883 | Z36: =Z35+1 -> 28 | AA36: =AA35+(AA35*0.02) -> 26.5302
N37: =N36+1 -> 29 | O37: =O36+(O36*0.0115) -> 26.16999 | Q37: =Q36+1 -> 29 | R37: =R36+(R36*0.0123) -> 26.25288 | T37: =T36+1 -> 29 | U37: =U36+(U36*0.0055) -> 24.143067 | W37: =W36+1 -> 29 | X37: =X36+(X36*0.0099) -> 24.444511 | Z37: =Z36+1 -> 29 | AA37: =AA36+(AA36*0.02) -> 27.060804
N38: =N37+1 -> 30 | O38: =O37+(O37*0.0115) -> 26.470945 | Q38: =Q37+1 -> 30 | R38: =R37+(R37*0.0123) -> 26.575791 | T38: =T37+1 -> 30 | U38: =U37+(U37*0.0055) -> 24.275853 | W38: =W37+1 -> 30 | X38: =X37+(X37*0.0099) -> 24.686512 | Z38: =Z37+1 -> 30 | AA38: =AA37+(AA37*0.02) -> 27.60202
N39: =N38+1 -> 31 | O39: =O38+(O38*0.0115) -> 26.775361 | Q39: =Q38+1 -> 31 | R39: =R38+(R38*0.0123) -> 26.902673 | T39: =T38+1 -> 31 | U39: =U38+(U38*0.0055) -> 24.409371 | W39: =W38+1 -> 31 | X39: =X38+(X38*0.0099) -> 24.930908 | Z39: =Z38+1 -> 31 | AA39: =AA38+(AA38*0.02) -> 28.15406
N40: =N39+1 -> 32 | O40: =O39+(O39*0.0115) -> 27.083277 | Q40: =Q39+1 -> 32 | R40: =R39+(R39*0.0123) -> 27.233576 | T40: =T39+1 -> 32 | U40: =U39+(U39*0.0055) -> 24.543622 | W40: =W39+1 -> 32 | X40: =X39+(X39*0.0099) -> 25.177724 | Z40: =Z39+1 -> 32 | AA40: =AA39+(AA39*0.02) -> 28.717142
N41: =N40+1 -> 33 | O41: =O40+(O40*0.0115) -> 27.394735 | Q41: =Q40+1 -> 33 | R41: =R40+(R40*0.0123) -> 27.568549 | T41: =T40+1 -> 33 | U41: =U40+(U40*0.0055) -> 24.678612 | W41: =W40+1 -> 33 | X41: =X40+(X40*0.0099) -> 25.426983 | Z41: =Z40+1 -> 33 | AA41: =AA40+(AA40*0.02) -> 29.291485
N42: =N41+1 -> 34 | O42: =O41+(O41*0.0115) -> 27.709775 | Q42: =Q41+1 -> 34 | R42: =R41+(R41*0.0123) -> 27.907642 | T42: =T41+1 -> 34 | U42: =U41+(U41*0.0055) -> 24.814345 | W42: =W41+1 -> 34 | X42: =X41+(X41*0.0099) -> 25.678711 | Z42: =Z41+1 -> 34 | AA42: =AA41+(AA41*0.02) -> 29.877314
N43: =N42+1 -> 35 | O43: =O42+(O42*0.0115) -> 28.028437 | Q43: =Q42+1 -> 35 | R43: =R42+(R42*0.0123) -> 28.250906 | T43: =T42+1 -> 35 | U43: =U42+(U42*0.0055) -> 24.950823 | W43: =W42+1 -> 35 | X43: =X42+(X42*0.0099) -> 25.93293 | Z43: =Z42+1 -> 35 | AA43: =AA42+(AA42*0.02) -> 30.47486

Sheet Average_30_Year_Old_Man_Profile
A1: Pillar | B1: Metric | D1: 1 | E1: 2 | F1: 3 | G1: 4 | H1: 5 | I1: 6 | J1: 7 | K1: 8 | L1: 9 | M1: 10 | R1: Combined Scores
A2: Vitality | B2: VO2 max (ml/kg/min) | C2: 43.4 | D2: =C2-(C2/100*D1) -> 42.966 | E2: =D2-(D2/100*E1) -> 42.10668 | F2: =E2-(E2/100*F1) -> 40.84348 | G2: =F2-(F2/100*G1) -> 39.20974 | H2: =G2-(G2/100*H1) -> 37.249253 | I2: =H2-(H2/100*I1) -> 35.014298 | J2: =I2-(I2/100*J1) -> 32.563297 | K2: =J2-(J2/100*K1) -> 29.958234 | ... M2: =L2-(L2/100*M1) -> 24.535793 | Q2: Vitality | R2: =B27+ ((1 -((C2 / 43.4) * 0.7 )-((C3 / 100) * 0.3 )) * 100) -> 30
A3: Vitality | B3: FEV1 (% predicted) | C3: 100 | D3: =C3-(C3/100*D1) -> 99 | E3: =D3-(D3/100*E1) -> 97.02 | F3: =E3-(E3/100*F1) -> 94.1094 | G3: =F3-(F3/100*G1) -> 90.345024 | H3: =G3-(G3/100*H1) -> 85.827773 | I3: =H3-(H3/100*I1) -> 80.678106 | J3: =I3-(I3/100*J1) -> 75.030639 | K3: =J3-(J3/100*K1) -> 69.028188 | ... M3: =L3-(L3/100*M1) -> 56.534086 | Q3: Strength | R3: =((O4/100*50)+(O5/100*25)+(O6/100*25)) -> 30 | T3: Functional Biological Age
A4: Strength & Power | B4: Grip strength (kg) | C4: 51 | D4: =C4-(C4/100*D1) -> 50.49 | E4: =D4-(D4/100*E1) -> 49.4802 | F4: =E4-(E4/100*F1) -> 47.995794 | G4: =F4-(F4/100*G1) -> 46.075962 | H4: =G4-(G4/100*H1) -> 43.772164 | I4: =H4-(H4/100*I1) -> 41.145834 | J4: =I4-(I4/100*J1) -> 38.265626 | K4: =J4-(J4/100*K1) -> 35.204376 | ... M4: =L4-(L4/100*M1) -> 28.832384 | O4: =IF(B27<30, FORECAST(C4, OFFSET(Strength_Normative_Data!$A$3, MATCH(C4, Strength_Normative_Data!$B$3:$B$5, 1)-1, 0, 2), OFFSET(Strength_Normative_Data!$B$3, MATCH(C4, Strength_Normative_Data!$B$3:$B$5, 1)-1, 0, 2)), FORECAST(C4, OFFSET(Strength_Normative_Data!$A$5, MATCH(C4, Strength_Normative_Data!$B$5:$B$16, -1)-1, 0, 2), OFFSET(Strength_Normative_Data!$B$5, MATCH(C4, Strength_Normative_Data!$B$5:$B$16, -1)-1, 0, 2))) -> 30 | Q4: Metabolic | R4: =B27 - 9*R11 -> 28.920406 | T4: =(R2/100*20)+(R3/100*20)+(R4/100*25)+(R5/100*20)+(R6/100*15) -> 29.730102
A5: Strength & Power | B5: STS Power (W/kg) | C5: 3.9 | M5: =C5-(C5/100*12) -> 3.432 | O5: =FORECAST(C5, OFFSET(Strength_Normative_Data!$O$3, MATCH(C5, Strength_Normative_Data!$P$3:$P$17, -1)-1, 0, 2), OFFSET(Strength_Normative_Data!$P$3, MATCH(C5, Strength_Normative_Data!$P$3:$P$17, -1)-1, 0, 2)) -> 30 | Q5: Functional Mobility | R5: =((O14/100*30)+(O15/100*25)+(O16/100*30)+(O17/100*15)) -> 30
A6: Strength & Power | B6: Vertical jump (cm) | C6: 49 | M6: =C6-(C6/100*12) -> 43.12 | O6: =FORECAST(C6, OFFSET(Strength_Normative_Data!$J$3, MATCH(C6, Strength_Normative_Data!$K$3:$K$16, -1)-1, 0, 2), OFFSET(Strength_Normative_Data!$K$3, MATCH(C6, Strength_Normative_Data!$K$3:$K$16, -1)-1, 0, 2)) -> 30 | Q6: Cognitive | R6: =((O18/100*60)+(O19/100*40)) -> 30
A7: Metabolic Health | B7: Body fat (%) | C7: 26 | M7: =C7+(C7/100*6) -> 27.56
A8: Metabolic Health | B8: Waist to height ratio | C8: 0.55 | M8: =C8+(C8/100*4) -> 0.572 | O8: =IF(C8<=0.4,0, IF(C8<=0.5,20*(C8-0.4)/0.1, IF(C8<=0.6,20+40*(C8-0.5)/0.1, 60+40*(MIN(C8,0.75)-0.6)/0.15))) -> 40
A9: Metabolic Health | B9: Fasting glucose (mmol/L) | C9: 5.6
A10: Metabolic Health | B10: HbA1c (%) | C10: 5.6 | M10: =C10+(C10/100*5) -> 5.88 | O10: =IF(C10<5.7,10*(C10/5.7), IF(C10<6.5,10+40*(C10-5.7)/0.8, 50+50*(MIN(C10,9)-6.5)/2.5)) -> 9.8245614 | Q10: Metabolic Index | R10: Metabolic Z score
A11: Metabolic Health | B11: HOMA IR | C11: 2.5 | M11: =C11+(C11/100*14) -> 2.85 | O11: =IF(C11<1.6,10*(C11/1.6), IF(C11<3,10+40*(C11-1.6)/1.4, 50+50*(MIN(C11,7)-3)/4)) -> 35.714286 | Q11: =(0.3*P12)+(0.2*O8)+(0.15*O10)+(0.25*O11)+(0.1*O13) -> 29.002256 | R11: =IF(Q11<=10,1.5-0.1*Q11, IF(Q11<=60,0.5-0.02*(Q11-10), -0.5-0.03*(Q11-60))) -> 0.11995489
A12: Metabolic Health | B12: ApoB (g/L) | C12: 0.98 | M12: =C12+(C12/100*6) -> 1.0388 | O12: =C12*100 -> 98 | P12: =IF(O12<80,5*(O12/80), IF(O12<100,10+20*(O12-80)/20, IF(O12<130,30+25*(O12-100)/30, IF(O12<160,55+25*(O12-130)/30, IF(O12<200,80+20*(O12-160)/40,100))))) -> 28
A13: Metabolic Health | B13: hsCRP (mg/L) | C13: 1.6 | M13: =C13+(C13/100*18) -> 1.888 | O13: =IF(C13<1,10*(C13/1), IF(C13<3,10+40*(C13-1)/2, 50+50*(MIN(C13,10)-3)/7)) -> 22
A14: Functional Mobility | B14: Gait speed (m/s) | C14: 1.43 | M14: =C14+(C14/100*6) -> 1.5158 | O14: 30
A15: Functional Mobility | B15: Timed Up and Go (sec) | C15: 5.5 | M15: =C15+(C15/100*10) -> 6.05 | O15: =FORECAST(C15, OFFSET(Mobility_Normative_Data!$E$3, MATCH(C15, Mobility_Normative_Data!$F$3:$F$18, 1)-1, 0, 2), OFFSET(Mobility_Normative_Data!$F$3, MATCH(C15, Mobility_Normative_Data!$F$3:$F$18, 1)-1, 0, 2)) -> 30
A16: Functional Mobility | B16: Single leg stance (sec) | C16: 43 | M16: =C16+(C16/100*20) -> 51.6 | O16: =FORECAST(C16, OFFSET(Mobility_Normative_Data!$I$3, MATCH(C16, Mobility_Normative_Data!$J$3:$J$17, -1)-1, 0, 2), OFFSET(Mobility_Normative_Data!$J$3, MATCH(C16, Mobility_Normative_Data!$J$3:$J$17, -1)-1, 0, 2)) -> 30
A17: Functional Mobility | B17: Sit and reach (cm) | C17: 37 | M17: =C17+(C17/100*10) -> 40.7 | O17: =FORECAST(C17, OFFSET(Mobility_Normative_Data!$M$3, MATCH(C17, Mobility_Normative_Data!$N$3:$N$17, -1)-1, 0, 2), OFFSET(Mobility_Normative_Data!$N$3, MATCH(C17, Mobility_Normative_Data!$N$3:$N$17, -1)-1, 0, 2)) -> 30
A18: Cognitive Performance | B18: Processing speed (SD) | C18: 0 | M18: =C18 +(-0.2) -> -0.2 | O18: =MAX(18,B27-(C18*25)) -> 30
A19: Cognitive Performance | B19: Working memory (SD) | C19: 0 | M19: =C19+(-0.2) -> -0.2 | O19: =MAX(18,B27-(J1925)) -> 30
A23: Overall Decline predicitons
B25: Present | C25: 10 years time | D25: 20 Years time | E25: Thirty years | F25: 40 years
A26: Sex | B26: Male
A27: Chronological | B27: 30 | C27: =B27+10 -> 40 | D27: =C27+10 -> 50 | E27: =D27+10 -> 60 | F27: =E27+10 -> 70
A28: Vitality | B28: =R2 -> 30 | C28: =B28+(B28/100*11.5) -> 33.45 | D28: =C28+(C28/100*32.2) -> 44.2209 | E28: =D28+(D28/100*32.2) -> 58.46003 | F28: =E28+(E28/100*32.2) -> 77.284159
A29: Strength | B29: =R3 -> 30 | C29: =B29+(B29/100*12.3) -> 33.69 | D29: =C29+(C29/100*30.8) -> 44.06652 | E29: =D29+(D29/100*30.8) -> 57.639008 | F29: =E29+(E29/100*30.8) -> 75.391823
A30: Metabolic | B30: =R4 -> 28.920406 | C30: =B30+(B30/100*5.5) -> 30.511028 | D30: =C30+(C30/100*11) -> 33.867241 | E30: =D30+(D30/100*11) -> 37.592638 | F30: =E30+(E30/100*11) -> 41.727828
A31: Mobility | B31: =R5 -> 30 | C31: =B31+(B31/100*9.9) -> 32.97 | D31: =C31+(C31/100*19.8) -> 39.49806 | E31: =D31+(D31/100*19.8) -> 47.318676 | F31: =E31+(E31/100*19.8) -> 56.687774 | N31: Graphing
A32: Cognitive | B32: =R6 -> 30 | C32: =B32+(B32/100*20) -> 36 | D32: =C32+(C32/100*60) -> 57.6 | E32: =D32+(D32/100*60) -> 92.16 | F32: =E32+(E32/100*60) -> 147.456 | N32: Chronological Age | O32: Vitality Decline of an average 30 Year old Man | Q32: Chronological Age | R32: Strength Decline of an average 30 Year old Man | T32: Chronological Age | U32: Metabolic Decline of an average 30 Year old Man | W32: Chronological Age | X32: Mobility Decline of an average 30 Year old Man | Z32: Chronological Age | AA32: Cognitive Decline of an average 30 Year old Man
N33: =B27 -> 30 | O33: =R2 -> 30 | Q33: =N33 -> 30 | R33: =R3 -> 30 | T33: =N33 -> 30 | U33: =R4 -> 28.920406 | W33: =N33 -> 30 | X33: =R5 -> 30 | Z33: =N33 -> 30 | AA33: =R6 -> 30
N34: =N33+1 -> 31 | O34: =O33+(O33*0.0115) -> 30.345 | Q34: =Q33+1 -> 31 | R34: =R33+(R33*0.0123) -> 30.369 | T34: =T33+1 -> 31 | U34: =U33+(U33*0.0055) -> 29.079468 | W34: =W33+1 -> 31 | X34: =X33+(X33*0.0099) -> 30.297 | Z34: =Z33+1 -> 31 | AA34: =AA33+(AA33*0.02) -> 30.6
N35: =N34+1 -> 32 | O35: =O34+(O34*0.0115) -> 30.693968 | Q35: =Q34+1 -> 32 | R35: =R34+(R34*0.0123) -> 30.742539 | T35: =T34+1 -> 32 | U35: =U34+(U34*0.0055) -> 29.239405 | W35: =W34+1 -> 32 | X35: =X34+(X34*0.0099) -> 30.59694 | Z35: =Z34+1 -> 32 | AA35: =AA34+(AA34*0.02) -> 31.212
A36: Functional Biological Age | N36: =N35+1 -> 33 | O36: =O35+(O35*0.0115) -> 31.046948 | Q36: =Q35+1 -> 33 | R36: =R35+(R35*0.0123) -> 31.120672 | T36: =T35+1 -> 33 | U36: =U35+(U35*0.0055) -> 29.400222 | W36: =W35+1 -> 33 | X36: =X35+(X35*0.0099) -> 30.89985 | Z36: =Z35+1 -> 33 | AA36: =AA35+(AA35*0.02) -> 31.83624
A37: =(B28/100*20)+(B29/100*20)+(B30/100*25)+(B31/100*20)+(B32/100*15) -> 29.730102 | N37: =N36+1 -> 34 | O37: =O36+(O36*0.0115) -> 31.403988 | Q37: =Q36+1 -> 34 | R37: =R36+(R36*0.0123) -> 31.503456 | T37: =T36+1 -> 34 | U37: =U36+(U36*0.0055) -> 29.561923 | W37: =W36+1 -> 34 | X37: =X36+(X36*0.0099) -> 31.205759 | Z37: =Z36+1 -> 34 | AA37: =AA36+(AA36*0.02) -> 32.472965
N38: =N37+1 -> 35 | O38: =O37+(O37*0.0115) -> 31.765134 | Q38: =Q37+1 -> 35 | R38: =R37+(R37*0.0123) -> 31.890949 | T38: =T37+1 -> 35 | U38: =U37+(U37*0.0055) -> 29.724514 | W38: =W37+1 -> 35 | X38: =X37+(X37*0.0099) -> 31.514696 | Z38: =Z37+1 -> 35 | AA38: =AA37+(AA37*0.02) -> 33.122424
N39: =N38+1 -> 36 | O39: =O38+(O38*0.0115) -> 32.130433 | Q39: =Q38+1 -> 36 | R39: =R38+(R38*0.0123) -> 32.283207 | T39: =T38+1 -> 36 | U39: =U38+(U38*0.0055) -> 29.887999 | W39: =W38+1 -> 36 | X39: =X38+(X38*0.0099) -> 31.826691 | Z39: =Z38+1 -> 36 | AA39: =AA38+(AA38*0.02) -> 33.784873
