Workbook

Sheet Vitality Normative Data
A1: VO2 Max Male | I1: VO2 Max Female | R1: FEV1
A2: Age Group | B2: 10th (Poor) | C2: 25th (Fair) | D2: 50th (Average) | E2: 75th (Good) | F2: 90th (Excellent) | G2: 95th (Superior) | I2: Age Group | J2: 10th (Poor) | K2: 25th (Fair) | L2: 50th (Average) | M2: 75th (Good) | N2: 90th (Excellent) | O2: 95th (Superior) | R2: Height (inches) | S2: Height (cm) | T2: Peak Male FEV1 (Liters) | U2: Peak Female FEV1 (Liters)
A3: 20-29 | B3: 33 | C3: 40.2 | D3: 48 | E3: 56.5 | F3: 64.1 | G3: 69.4 | I3: 20-29 | J3: 23.6 | K3: 28.9 | L3: 37.6 | M3: 44.5 | N3: 51.5 | O3: 55.4 | Q3: 5 foot | R3: 60 | S3: 152 | T3: 3.25 | U3: 2.55
A4: 30-39 | B4: 29.5 | C4: 35.5 | D4: 43.4 | E4: 52.5 | F4: 58.7 | G4: 64.4 | I4: 30-39 | J4: 21.8 | K4: 26.5 | L4: 34.7 | M4: 41 | N4: 47 | O4: 50.8 | R4: 61 | S4: 155 | T4: 3.35 | U4: 2.65
A5: 40-49 | B5: 25.6 | C5: 32.1 | D5: 39.5 | E5: 47.4 | F5: 54.5 | G5: 59.9 | I5: 40-49 | J5: 19 | K5: 24.1 | L5: 30.6 | M5: 36.7 | N5: 42.1 | O5: 46.1 | R5: 62 | S5: 157 | T5: 3.45 | U5: 2.7
A6: 50-59 | B6: 23.3 | C6: 28.6 | D6: 34.5 | E6: 41.5 | F6: 48 | G6: 52.8 | I6: 50-59 | J6: 17 | K6: 21.3 | L6: 26.6 | M6: 31.9 | N6: 36.4 | O6: 39.5 | R6: 63 | S6: 160 | T6: 3.55 | U6: 2.8
A7: 60-69 | B7: 19.3 | C7: 24.3 | D7: 30.2 | E7: 36.3 | F7: 42.1 | G7: 46.4 | I7: 60-69 | J7: 14.7 | K7: 18.2 | L7: 22.8 | M7: 27.2 | N7: 31.3 | O7: 34.6 | R7: 64 | S7: 163 | T7: 3.7 | U7: 2.9
A8: 70-79 | B8: 16.5 | C8: 20.2 | D8: 25.2 | E8: 30.5 | F8: 36.3 | G8: 41.2 | I8: 70-79 | J8: 13 | K8: 16.1 | L8: 20.4 | M8: 24 | N8: 27.7 | O8: 30.7 | R8: 65 | S8: 165 | T8: 3.8 | U8: 3
R9: 66 | S9: 168 | T9: 3.95 | U9: 3.05
R10: 67 | S10: 170 | T10: 4.05 | U10: 3.15
R11: 68 | S11: 173 | T11: 4.2 | U11: 3.25
R12: 69 | S12: 175 | T12: 4.3 | U12: 3.35
R13: 70 | S13: 178 | T13: 4.45 | U13: 3.45
R14: 71 | S14: 180 | T14: 4.55 | U14: 3.5
C15: VO2 Max Taken from the Cooper Institue for Aerobics Research Dallas TX | Q15: 6 foot | R15: 72 | S15: 183 | T15: 4.7 | U15: 3.6
R16: 73 | S16: 185 | T16: 4.85 | U16: 3.7
R17: 74 | S17: 188 | T17: 5 | U17: 3.8
R18: 75 | S18: 190 | T18: 5.15 | U18: 3.9
R21: You should use a spirometry software package that calculates predicted FEV1 values (and other lung function parameters) based on Global Lung Function Initiative (GLI) 2012 reference equations, inputting the individual's age, sex, height, and ethnicity

Sheet Strength_Normative_Data
A1: Grip Strength | J1: Vertical Jump | O1: Sit to Stand
A2: Age | B2: Male Grip (kg) | C2: Female Grip (kg) | J2: Age | K2: Male Jump (cm) | L2: Female Jump (cm) | O2: Age | P2: Male Power (W/kg) | Q2: Female Power (W/kg)
A3: 20 | B3: 48 | C3: 29 | J3: 20 | K3: 53 | L3: 35 | O3: 20 | P3: 4.3 | Q3: 3.2
A4: 25 | B4: 50 | C4: 30 | J4: 25 | K4: 51 | L4: 33.5 | O4: 25 | P4: 4.1 | Q4: 3.1
A5: 30 | B5: 51 | C5: 31 | J5: 30 | K5: 49 | L5: 32 | O5: 30 | P5: 3.9 | Q5: 3
A6: 35 | B6: 50 | C6: 31 | J6: 35 | K6: 46.5 | L6: 30 | O6: 35 | P6: 3.7 | Q6: 2.85
A7: 40 | B7: 49 | C7: 30 | J7: 40 | K7: 44 | L7: 28 | O7: 40 | P7: 3.5 | Q7: 2.7
A8: 45 | B8: 47 | C8: 29 | J8: 45 | K8: 41.5 | L8: 26 | O8: 45 | P8: 3.3 | Q8: 2.55
A9: 50 | B9: 46 | C9: 28 | J9: 50 | K9: 39 | L9: 24 | O9: 50 | P9: 3.1 | Q9: 2.4
A10: 55 | B10: 44 | C10: 27 | J10: 55 | K10: 35.5 | L10: 21.5 | O10: 55 | P10: 2.9 | Q10: 2.25
A11: 60 | B11: 42 | C11: 25 | J11: 60 | K11: 32 | L11: 19 | O11: 60 | P11: 2.7 | Q11: 2.1
A12: 65 | B12: 39 | C12: 23 | J12: 65 | K12: 28.5 | L12: 16.5 | O12: 65 | P12: 2.5 | Q12: 1.95
A13: 70 | B13: 36 | C13: 21 | J13: 70 | K13: 25 | L13: 14 | O13: 70 | P13: 2.3 | Q13: 1.8
A14: 75 | B14: 33 | C14: 19 | J14: 75 | K14: 21.5 | L14: 12 | O14: 75 | P14: 2.1 | Q14: 1.65
A15: 80 | B15: 30 | C15: 17 | J15: 80 | K15: 18 | L15: 10 | O15: 80 | P15: 1.9 | Q15: 1.5
A16: 85 | B16: 26 | C16: 14 | O16: 85 | P16: 1.7 | Q16: 1.35
O17: 90 | P17: 1.5 | Q17: 1.2
A18: Source: https://journals.plos.org/plosone/article?id=10.1371/journal.pone.0113637 | J18: https://go.gale.com/ps/i.do?id=GALE%7CA649711026&sid=googleScholar&v=2.1&it=r&linkaccess=abs&issn=08406529&p=AONE&sw=w&userGroupName=anon%7Eda6c86b0&aty=open-web-entry | O18: https://www.nature.com/articles/s41598-020-73395-4
J19: linked article references canadian health measures suvery which is where normative data originates from | O19: Derived from Toledo study for healthy aging in spain

Sheet Mobility_Normative_Data
A1: Gait Speed | E1: TUG | I1: Single Leg Stance | M1: Sit and Reach
A2: Age | B2: Male (m/s) | C2: Female (m/s) | E2: Age | F2: Male (sec) | G2: Female (sec) | I2: Age | J2: Male (sec) | K2: Female (sec) | M2: Age | N2: Male (cm) | O2: Female (cm)
A3: 20 | B3: 1.36 | C3: 1.34 | E3: 18 | F3: 3 | G3: 3 | I3: 20 | J3: 45 | K3: 45 | M3: 20 | N3: 39 | O3: 42
A4: 25 | B4: 1.36 | C4: 1.34 | E4: 20 | F4: 5 | G4: 5.5 | I4: 25 | J4: 44 | K4: 44 | M4: 25 | N4: 38 | O4: 41
A5: 30 | B5: 1.43 | C5: 1.34 | E5: 25 | F5: 5.2 | G5: 5.8 | I5: 30 | J5: 43 | K5: 43 | M5: 30 | N5: 37 | O5: 40
A6: 35 | B6: 1.43 | C6: 1.34 | E6: 30 | F6: 5.5 | G6: 6 | I6: 35 | J6: 41 | K6: 41 | M6: 35 | N6: 36 | O6: 38
A7: 40 | B7: 1.43 | C7: 1.39 | E7: 35 | F7: 5.8 | G7: 6.2 | I7: 40 | J7: 39 | K7: 39 | M7: 40 | N7: 34 | O7: 37
A8: 45 | B8: 1.43 | C8: 1.39 | E8: 40 | F8: 6 | G8: 6.5 | I8: 45 | J8: 37 | K8: 37 | M8: 45 | N8: 32.5 | O8: 35.5
A9: 50 | B9: 1.43 | C9: 1.31 | E9: 45 | F9: 6.5 | G9: 7 | I9: 50 | J9: 35 | K9: 35 | M9: 50 | N9: 31 | O9: 34
A10: 55 | B10: 1.43 | C10: 1.31 | E10: 50 | F10: 7 | G10: 7.5 | I10: 55 | J10: 33 | K10: 32 | M10: 55 | N10: 29.5 | O10: 32.5
A11: 60 | B11: 1.33 | C11: 1.24 | E11: 55 | F11: 7.5 | G11: 8 | I11: 60 | J11: 30 | K11: 29 | M11: 60 | N11: 28 | O11: 31
A12: 65 | B12: 1.33 | C12: 1.24 | E12: 60 | F12: 8 | G12: 8.5 | I12: 65 | J12: 25 | K12: 22 | M12: 65 | N12: 26.5 | O12: 30
A13: 70 | B13: 1.26 | C13: 1.13 | E13: 65 | F13: 8.5 | G13: 9 | I13: 70 | J13: 20 | K13: 16 | M13: 70 | N13: 25 | O13: 29
A14: 75 | B14: 1.26 | C14: 1.13 | E14: 70 | F14: 9 | G14: 9.5 | I14: 75 | J14: 15 | K14: 11 | M14: 75 | N14: 23.5 | O14: 27.5
A15: 80 | B15: 1.26 | C15: 1.13 | E15: 75 | F15: 9.5 | G15: 10 | I15: 80 | J15: 10 | K15: 7 | M15: 80 | N15: 22 | O15: 26
E16: 80 | F16: 10 | G16: 11 | I16: 85 | J16: 7 | K16: 5 | M16: 85 | N16: 20.5 | O16: 25
E17: 85 | F17: 11 | G17: 12 | I17: 90 | J17: 5 | K17: 3 | M17: 90 | N17: 19 | O17: 24
E18: 90 | F18: 12 | G18: 13
E19: Seems to based off Kearney, P. M., et al. (2013). "Cohort Profile: The Irish Longitudinal Study on Ageing." International Journal of Epidemiology, 40(4), 877-884.
A24: Gait speed | H24: Timed up and go | M24: Single Leg stance | R24: Sit and reach
A25: Age Group | B25: Male (Comfortable) | C25: Male (Maximum) | D25: Female (Comfortable) | E25: Female (Maximum) | H25: Age Group | I25: Mean Time (Seconds) | J25: 95% Confidence Interval | M25: Age Group | N25: Eyes OPEN (Mean ± SD) | O25: Eyes CLOSED (Mean ± SD) | R25: Age Group | S25: Male (cm) | T25: Female (cm)
A26: 20–29 | B26: 1.36 | C26: 2.53 | D26: 1.34 | E26: 2.47 (0.25) | H26: 60–69 | I26: 8.1 | J26: 7.1 – 9.0 | M26: 18–39 | N26: 45.1 (±0.1) | O26: 13.1 (±10.3) | R26: 20–29 | S26: 30 | T26: 33
A27: 30–39 | B27: 1.43 | C27: 2.46 | D27: 1.34 | E27: 2.34 | H27: 70–79 | I27: 9.2 | J27: 8.2 – 10.2 | M27: 40–49 | N27: 42.1 (±9.5) | O27: 13.5 (±8.8) | R27: 30–39 | S27: 28 | T27: 32
A28: 40–49 | B28: 1.43 | C28: 2.46 | D28: 1.39 | E28: 2.12 | H28: 80–99 | I28: 11.3 | J28: 10.0 – 12.7 | M28: 50–59 | N28: 40.9 (±9.9) | O28: 7.9 (±6.6) | R28: 40–49 | S28: 24 | T28: 30
A29: 50–59 | B29: 1.43 | C29: 2.14 | D29: 1.31 | E29: 2.01 | M29: 60–69 | N29: 30.4 (±16.4) | O29: 3.7 (±1.8) | R29: 50–59 | S29: 24 | T29: 30
A30: 60–69 | B30: 1.33 | C30: 1.93 | D30: 1.24 | E30: 1.77 | M30: 70–79 | N30: 16.7 (±15.3) | O30: 2.5 (±1.6) | R30: 60+ | S30: 20 | T30: 27
A31: 70–79 | B31: 1.26 | C31: 2.07 | D31: 1.13 | E31: 1.75 | M31: 80–99 | N31: 10.6 (±12.9) | O31: 1.8 (±1.4)
B33: Bohannon norms Gait speed Link: https://academic.oup.com/ageing/article-abstract/26/1/15/35875?redirectedFrom=fulltext&login=false | H33: The Real "Gold Standard" Data The most cited and reliable source for Timed Up and Go (TUG) norms comes from the meta-analysis by Bohannon (2006). Source: Reference values for the Timed Up and Go Test: A Descriptive Meta-Analysis, published in the Journal of Geriatric Physical Therapy. Here is the Bohannon (2006) data. You will notice it doesn't bother with ages under 60, because the test is clinically irrelevant for younger populations unless they have a specific injury. | M33: Springer, B.A., Marin, R., Cyhan, T., Roberts, H. and Gill, N.W. (2007) ‘Normative values for the unipedal stance test with eyes open and closed’, Journal of Geriatric Physical Therapy, 30(1), pp. 8–15 | R33: American College of Sports Medicine (2021) ACSM’s Guidelines for Exercise Testing and Prescription. 11th edn. Philadelphia: Wolters Kluwer

Sheet Metabolic_Normative_Data
B1: ApoB | C1: WHtR | D1: HOMA | E1: HbA1c | F1: hscrp | H1: 15 | J1: AgeMin | K1: AgeMax | L1: Sex | M1: BaseIndex
A2: Low risk | B2: <90 | C2: <0.5 | D2: <1.5 | E2: 4.0 - 5.4 | F2: <1 | H2: 8 | J2: 18 | K2: 29 | L2: Any | M2: 8
A3: Normal | B3: 90 - 129 | C3: 0.5 - 0.59 | D3: 1.5 - 2.4 | E3: 5.5 - 5.6 | F3: 1.0 - 3.0 | J3: 30 | K3: 39 | L3: Any | M3: 8.8
A4: Elevated | B4: >130 | C4: >0.6 | D4: >2.5 | E4: >5.7 | F4: >3 | J4: 40 | K4: 49 | L4: Any | M4: 9.6
J5: 50 | K5: 59 | L5: Any | M5: 10.5
J6: 60 | K6: 69 | L6: Any | M6: 11.5
J7: 70 | K7: 79 | L7: Any | M7: 12.5

Sheet Average_20_Year_Old_Man_Pro
A1: Pillar | B1: Metric | R1: Combined Scores
A2: Vitality | B2: VO2 max (ml/kg/min) | C2: 48 | Q2: Vitality | R2: =B27+ ((1 -((C2 / 48) * 0.7 )-((C3 / 100) * 0.3 )) * 100) -> 20
A3: Vitality | B3: FEV1 (% predicted) | C3: 100 | Q3: Strength | R3: =((O4/100*50)+(O5/100*25)+(O6/100*25)) -> 20 | T3: Functional Biological Age
A4: Strength & Power | B4: Grip strength (kg) | C4: 48 | O4: =IF(B27<30, FORECAST(C4, OFFSET(Strength_Normative_Data!$A$3, MATCH(C4, Strength_Normative_Data!$B$3:$B$5, 1)-1, 0, 2), OFFSET(Strength_Normative_Data!$B$3, MATCH(C4, Strength_Normative_Data!$B$3:$B$5, 1)-1, 0, 2)), FORECAST(C4, OFFSET(Strength_Normative_Data!$A$5, MATCH(C4, Strength_Normative_Data!$B$5:$B$16, -1)-1, 0, 2), OFFSET(Strength_Normative_Data!$B$5, MATCH(C4, Strength_Normative_Data!$B$5:$B$16, -1)-1, 0, 2))) -> 20 | Q4: Metabolic | R4: {=_xlfn.LET( _xlpm.idx, Q11, _xlpm.age, B27, _xlpm.sex, C27, _xlpm.span, --Metabolic_Normative_Data!$H$1, _xlpm.t, Metabolic_Normative_Data!$J$2:$M$20, _xlpm.mins, INDEX(_xlpm.t,,1), _xlpm.maxs, INDEX(_xlpm.t,,2), _xlpm.sexes, INDEX(_xlpm.t,,3), _xlpm.bases, INDEX(_xlpm.t,,4), _xlpm.r, _xlfn.XMATCH(1,(_xlpm.age>=_xlpm.mins)*(_xlpm.age<=_xlpm.maxs)*((_xlpm.sexes=_xlpm.sex)+(_xlpm.sexes="Any")>0),0), _xlpm.base, INDEX(_xlpm.bases,_xlpm.r), _xlpm.delta, (_xlpm.idx-_xlpm.base)*(_xlpm.span/_xlpm.base), _xlpm.age + MAX(-_xlpm.span, MIN(_xlpm.span, _xlpm.delta)) )} -> 20.28125 | T4: =(R2/100*20)+(R3/100*20)+(R4/100*25)+(R5/100*20)+(R6/100*15) -> 20.070312
A5: Strength & Power | B5: STS Power (W/kg) | C5: 4.3 | O5: =FORECAST(C5, OFFSET(Strength_Normative_Data!$O$3, MATCH(C5, Strength_Normative_Data!$P$3:$P$17, -1)-1, 0, 2), OFFSET(Strength_Normative_Data!$P$3, MATCH(C5, Strength_Normative_Data!$P$3:$P$17, -1)-1, 0, 2)) -> 20 | Q5: Functional Mobility | R5: =((O14/100*30)+(O15/100*25)+(O16/100*30)+(O17/100*15)) -> 20
A6: Strength & Power | B6: Vertical jump (cm) | C6: 53 | O6: =FORECAST(C6, OFFSET(Strength_Normative_Data!$J$3, MATCH(C6, Strength_Normative_Data!$K$3:$K$16, -1)-1, 0, 2), OFFSET(Strength_Normative_Data!$K$3, MATCH(C6, Strength_Normative_Data!$K$3:$K$16, -1)-1, 0, 2)) -> 20 | Q6: Cognitive | R6: =((O18/100*60)+(O19/100*40)) -> 20
A7: Metabolic Health | B7: Body fat (%) | C7: 22
A8: Metabolic Health | B8: Waist to height ratio | C8: 0.48 | O8: {=_xlfn.LET( _xlpm.x, C8, _xlpm.mk, "WHtR", _xlpm.hdr, Metabolic_Normative_Data!$B$1:$F$1, _xlpm.rows, Metabolic_Normative_Data!$A$2:$A$4, _xlpm.dat, Metabolic_Normative_Data!$B$2:$F$4, _xlpm.c, _xlfn.XMATCH(_xlpm.mk, _xlpm.hdr), _xlpm.sLow, INDEX(_xlpm.dat, _xlfn.XMATCH("Low risk", _xlpm.rows), _xlpm.c), _xlpm.sNor, INDEX(_xlpm.dat, _xlfn.XMATCH("Normal", _xlpm.rows), _xlpm.c), _xlpm.sElev,INDEX(_xlpm.dat, _xlfn.XMATCH("Elevated", _xlpm.rows),_xlpm.c), _xlpm.clean, _xlfn.LAMBDA(_xlpm.s, SUBSTITUTE(SUBSTITUTE(TRIM(_xlpm.s)," ",""),"–","-")), _xlpm.hiFrom, _xlfn.LAMBDA(_xlpm.s, _xlfn.LET(_xlpm.t, CLEAN(_xlpm.s), IF(LEFT(_xlpm.t,1)="<", VALUE(MID(_xlpm.t,2,99)), IF(ISNUMBER(SEARCH("-",_xlpm.t)), VALUE(_xlfn.TEXTAFTER(_xlpm.t,"-")), 1E+99) ) ) ), _xlpm.loFrom, _xlfn.LAMBDA(_xlpm.s, _xlfn.LET(_xlpm.t, CLEAN(_xlpm.s), IF(LEFT(_xlpm.t,1)=">", VALUE(MID(_xlpm.t,2,99)), IF(ISNUMBER(SEARCH("-",_xlpm.t)), VALUE(_xlfn.TEXTBEFORE(_xlpm.t,"-")), -1E+99) ) ) ), _xlpm.lowMax, _xlpm.hiFrom(_xlpm.sLow), _xlpm.norMin, _xlpm.loFrom(_xlpm.sNor), _xlpm.norMax, _xlpm.hiFrom(_xlpm.sNor), _xlpm.elevMin, _xlpm.loFrom(_xlpm.sElev), _xlpm.span, MAX(_xlpm.norMax-_xlpm.lowMax, 0.000001), _xlpm.score, IF(_xlpm.x<=_xlpm.lowMax, 5, IF(_xlpm.x<_xlpm.elevMin, 5 + 30 * (_xlpm.x-_xlpm.lowMax) / MAX(_xlpm.elevMin-_xlpm.lowMax,0.000001), 35 + 65 * (_xlpm.x-_xlpm.elevMin) / (2*_xlpm.span) ) ), MAX(0, MIN(100, _xlpm.score)) )} -> 5
A9: Metabolic Health | B9: Fasting glucose (mmol/L) | C9: 5.1
A10: Metabolic Health | B10: HbA1c (%) | C10: 5.3 | O10: {=_xlfn.LET( _xlpm.x, C10, _xlpm.mk, "HbA1c", _xlpm.hdr, Metabolic_Normative_Data!$B$1:$F$1, _xlpm.rows, Metabolic_Normative_Data!$A$2:$A$4, _xlpm.dat, Metabolic_Normative_Data!$B$2:$F$4, _xlpm.c, _xlfn.XMATCH(_xlpm.mk, _xlpm.hdr), _xlpm.sLow, INDEX(_xlpm.dat, _xlfn.XMATCH("Low risk", _xlpm.rows), _xlpm.c), _xlpm.sNor, INDEX(_xlpm.dat, _xlfn.XMATCH("Normal", _xlpm.rows), _xlpm.c), _xlpm.sElev,INDEX(_xlpm.dat, _xlfn.XMATCH("Elevated", _xlpm.rows),_xlpm.c), _xlpm.clean, _xlfn.LAMBDA(_xlpm.s, SUBSTITUTE(SUBSTITUTE(TRIM(_xlpm.s)," ",""),"–","-")), _xlpm.hiFrom, _xlfn.LAMBDA(_xlpm.s, _xlfn.LET(_xlpm.t, CLEAN(_xlpm.s), IF(LEFT(_xlpm.t,1)="<", VALUE(MID(_xlpm.t,2,99)), IF(ISNUMBER(SEARCH("-",_xlpm.t)), VALUE(_xlfn.TEXTAFTER(_xlpm.t,"-")), 1E+99) ) ) ), _xlpm.loFrom, _xlfn.LAMBDA(_xlpm.s, _xlfn.LET(_xlpm.t, CLEAN(_xlpm.s), IF(LEFT(_xlpm.t,1)=">", VALUE(MID(_xlpm.t,2,99)), IF(ISNUMBER(SEARCH("-",_xlpm.t)), VALUE(_xlfn.TEXTBEFORE(_xlpm.t,"-")), -1E+99) ) ) ), _xlpm.lowMax, _xlpm.hiFrom(_xlpm.sLow), _xlpm.norMin, _xlpm.loFrom(_xlpm.sNor), _xlpm.norMax, _xlpm.hiFrom(_xlpm.sNor), _xlpm.elevMin, _xlpm.loFrom(_xlpm.sElev), _xlpm.span, MAX(_xlpm.norMax-_xlpm.lowMax, 0.000001), _xlpm.score, IF(_xlpm.x<=_xlpm.lowMax, 5, IF(_xlpm.x<_xlpm.elevMin, 5 + 30 * (_xlpm.x-_xlpm.lowMax) / MAX(_xlpm.elevMin-_xlpm.lowMax,0.000001), 35 + 65 * (_xlpm.x-_xlpm.elevMin) / (2*_xlpm.span) ) ), MAX(0, MIN(100, _xlpm.score)) )} -> 5 | Q10: Metabolic Index
A11: Metabolic Health | B11: HOMA IR | C11: 1.8 | O11: {=_xlfn.LET( _xlpm.x, C11, _xlpm.mk, "Homa", _xlpm.hdr, Metabolic_Normative_Data!$B$1:$F$1, _xlpm.rows, Metabolic_Normative_Data!$A$2:$A$4, _xlpm.dat, Metabolic_Normative_Data!$B$2:$F$4, _xlpm.c, _xlfn.XMATCH(_xlpm.mk, _xlpm.hdr), _xlpm.sLow, INDEX(_xlpm.dat, _xlfn.XMATCH("Low risk", _xlpm.rows), _xlpm.c), _xlpm.sNor, INDEX(_xlpm.dat, _xlfn.XMATCH("Normal", _xlpm.rows), _xlpm.c), _xlpm.sElev,INDEX(_xlpm.dat, _xlfn.XMATCH("Elevated", _xlpm.rows),_xlpm.c), _xlpm.clean, _xlfn.LAMBDA(_xlpm.s, SUBSTITUTE(SUBSTITUTE(TRIM(_xlpm.s)," ",""),"–","-")), _xlpm.hiFrom, _xlfn.LAMBDA(_xlpm.s, _xlfn.LET(_xlpm.t, CLEAN(_xlpm.s), IF(LEFT(_xlpm.t,1)="<", VALUE(MID(_xlpm.t,2,99)), IF(ISNUMBER(SEARCH("-",_xlpm.t)), VALUE(_xlfn.TEXTAFTER(_xlpm.t,"-")), 1E+99) ) ) ), _xlpm.loFrom, _xlfn.LAMBDA(_xlpm.s, _xlfn.LET(_xlpm.t, CLEAN(_xlpm.s), IF(LEFT(_xlpm.t,1)=">", VALUE(MID(_xlpm.t,2,99)), IF(ISNUMBER(SEARCH("-",_xlpm.t)), VALUE(_xlfn.TEXTBEFORE(_xlpm.t,"-")), -1E+99) ) ) ), _xlpm.lowMax, _xlpm.hiFrom(_xlpm.sLow), _xlpm.norMin, _xlpm.loFrom(_xlpm.sNor), _xlpm.norMax, _xlpm.hiFrom(_xlpm.sNor), _xlpm.elevMin, _xlpm.loFrom(_xlpm.sElev), _xlpm.span, MAX(_xlpm.norMax-_xlpm.lowMax, 0.000001), _xlpm.score, IF(_xlpm.x<=_xlpm.lowMax, 5, IF(_xlpm.x<_xlpm.elevMin, 5 + 30 * (_xlpm.x-_xlpm.lowMax) / MAX(_xlpm.elevMin-_xlpm.lowMax,0.000001), 35 + 65 * (_xlpm.x-_xlpm.elevMin) / (2*_xlpm.span) ) ), MAX(0, MIN(100, _xlpm.score)) )} -> 14 | Q11: =(0.3*P12)+(0.2*O8)+(0.15*O10)+(0.25*O11)+(0.1*O13) -> 8.15
A12: Metabolic Health | B12: ApoB (g/L) | C12: 0.85 | O12: =C12*100 -> 85 | P12: {=_xlfn.LET( _xlpm.x, C12, _xlpm.mk, "ApoB", _xlpm.hdr, Metabolic_Normative_Data!$B$1:$F$1, _xlpm.rows, Metabolic_Normative_Data!$A$2:$A$4, _xlpm.dat, Metabolic_Normative_Data!$B$2:$F$4, _xlpm.c, _xlfn.XMATCH(_xlpm.mk, _xlpm.hdr), _xlpm.sLow, INDEX(_xlpm.dat, _xlfn.XMATCH("Low risk", _xlpm.rows), _xlpm.c), _xlpm.sNor, INDEX(_xlpm.dat, _xlfn.XMATCH("Normal", _xlpm.rows), _xlpm.c), _xlpm.sElev,INDEX(_xlpm.dat, _xlfn.XMATCH("Elevated", _xlpm.rows),_xlpm.c), _xlpm.clean, _xlfn.LAMBDA(_xlpm.s, SUBSTITUTE(SUBSTITUTE(TRIM(_xlpm.s)," ",""),"–","-")), _xlpm.hiFrom, _xlfn.LAMBDA(_xlpm.s, _xlfn.LET(_xlpm.t, CLEAN(_xlpm.s), IF(LEFT(_xlpm.t,1)="<", VALUE(MID(_xlpm.t,2,99)), IF(ISNUMBER(SEARCH("-",_xlpm.t)), VALUE(_xlfn.TEXTAFTER(_xlpm.t,"-")), 1E+99) ) ) ), _xlpm.loFrom, _xlfn.LAMBDA(_xlpm.s, _xlfn.LET(_xlpm.t, CLEAN(_xlpm.s), IF(LEFT(_xlpm.t,1)=">", VALUE(MID(_xlpm.t,2,99)), IF(ISNUMBER(SEARCH("-",_xlpm.t)), VALUE(_xlfn.TEXTBEFORE(_xlpm.t,"-")), -1E+99) ) ) ), _xlpm.lowMax, _xlpm.hiFrom(_xlpm.sLow), _xlpm.norMin, _xlpm.loFrom(_xlpm.sNor), _xlpm.norMax, _xlpm.hiFrom(_xlpm.sNor), _xlpm.elevMin, _xlpm.loFrom(_xlpm.sElev), _xlpm.span, MAX(_xlpm.norMax-_xlpm.lowMax, 0.000001), _xlpm.score, IF(_xlpm.x<=_xlpm.lowMax, 5, IF(_xlpm.x<_xlpm.elevMin, 5 + 30 * (_xlpm.x-_xlpm.lowMax) / MAX(_xlpm.elevMin-_xlpm.lowMax,0.000001), 35 + 65 * (_xlpm.x-_xlpm.elevMin) / (2*_xlpm.span) ) ), MAX(0, MIN(100, _xlpm.score)) )} -> 5
A13: Metabolic Health | B13: hsCRP (mg/L) | C13: 1.2 | O13: =IF(C13<1,10*(C13/1), IF(C13<3,10+40*(C13-1)/2, 50+50*(MIN(C13,10)-3)/7)) -> 14
A14: Functional Mobility | B14: Gait speed (m/s) | C14: 1.36 | O14: =IFERROR(FORECAST(C14, OFFSET(Mobility_Normative_Data!$A$3, MATCH(C14, Mobility_Normative_Data!$B$3:$B$17, -1)-1, 0, 2), OFFSET(Mobility_Normative_Data!$B$3, MATCH(C14, Mobility_Normative_Data!$B$3:$B$17, -1)-1, 0, 2)), INDEX(Mobility_Normative_Data!$A$3:$A$17, MATCH(C14, Mobility_Normative_Data!$B$3:$B$17, -1))) -> 20
A15: Functional Mobility | B15: Timed Up and Go (sec) | C15: 5 | O15: =FORECAST(C15, OFFSET(Mobility_Normative_Data!$E$3, MATCH(C15, Mobility_Normative_Data!$F$3:$F$18, 1)-1, 0, 2), OFFSET(Mobility_Normative_Data!$F$3, MATCH(C15, Mobility_Normative_Data!$F$3:$F$18, 1)-1, 0, 2)) -> 20
A16: Functional Mobility | B16: Single leg stance (sec) | C16: 45 | O16: =FORECAST(C16, OFFSET(Mobility_Normative_Data!$I$3, MATCH(C16, Mobility_Normative_Data!$J$3:$J$17, -1)-1, 0, 2), OFFSET(Mobility_Normative_Data!$J$3, MATCH(C16, Mobility_Normative_Data!$J$3:$J$17, -1)-1, 0, 2)) -> 20
A17: Functional Mobility | B17: Sit and reach (cm) | C17: 39 | O17: =FORECAST(C17, OFFSET(Mobility_Normative_Data!$M$3, MATCH(C17, Mobility_Normative_Data!$N$3:$N$17, -1)-1, 0, 2), OFFSET(Mobility_Normative_Data!$N$3, MATCH(C17, Mobility_Normative_Data!$N$3:$N$17, -1)-1, 0, 2)) -> 20
A18: Cognitive Performance | B18: Processing speed (SD) | C18: 0 | O18: =MAX(18,B27-(C18*25)) -> 20
A19: Cognitive Performance | B19: Working memory (SD) | C19: 0 | O19: =MAX(18,B27-(J1925)) -> 20
A23: Overall Decline predicitons
B25: Present | C25: 10 years time | D25: 20 Years time | E25: Thirty years | F25: 40 years
A26: Sex | B26: Any
A27: Chronological | B27: 20 | C27: =B27+10 -> 30 | D27: =C27+10 -> 40 | E27: =D27+10 -> 50 | F27: =E27+10 -> 60
A28: Vitality | B28: =R2 -> 20 | C28: =B28+(B28/100*11.5) -> 22.3 | D28: =C28+(C28/100*32.2) -> 29.4806 | E28: =D28+(D28/100*32.2) -> 38.973353 | F28: =E28+(E28/100*32.2) -> 51.522773
A29: Strength | B29: =R3 -> 20 | C29: =B29+(B29/100*12.3) -> 22.46 | D29: =C29+(C29/100*30.8) -> 29.37768 | E29: =D29+(D29/100*30.8) -> 38.426005 | F29: =E29+(E29/100*30.8) -> 50.261215
A30: Metabolic | B30: =R4 -> 20.28125 | C30: =B30+(B30/100*5.5) -> 21.396719 | D30: =C30+(C30/100*11) -> 23.750358 | E30: =D30+(D30/100*11) -> 26.362897 | F30: =E30+(E30/100*11) -> 29.262816
A31: Mobility | B31: =R5 -> 20 | C31: =B31+(B31/100*9.9) -> 21.98 | D31: =C31+(C31/100*19.8) -> 26.33204 | E31: =D31+(D31/100*19.8) -> 31.545784 | F31: =E31+(E31/100*19.8) -> 37.791849 | N31: Graphing
A32: Cognitive | B32: =R6 -> 20 | C32: =B32+(B32/100*20) -> 24 | D32: =C32+(C32/100*60) -> 38.4 | E32: =D32+(D32/100*60) -> 61.44 | F32: =E32+(E32/100*60) -> 98.304 | N32: Chronological Age | O32: Vitality Decline of an average 20 Year old Man | Q32: Chronological Age | R32: Strength Decline of an average 20 Year old Man | T32: Chronological Age | U32: Metabolic Decline of an average 20 Year old Man | W32: Chronological Age | X32: Mobility Decline of an average 20 Year old Man | Z32: Chronological Age | AA32: Cognitive Decline of an average 20 Year old Man
N33: =B27 -> 20 | O33: =R2 -> 20 | Q33: =N33 -> 20 | R33: =R3 -> 20 | T33: =N33 -> 20 | U33: =R4 -> 20.28125 | W33: =N33 -> 20 | X33: =R5 -> 20 | Z33: =N33 -> 20 | AA33: =R6 -> 20
N34: =N33+1 -> 21 | O34: =O33+(O33*0.0115) -> 20.23 | Q34: =Q33+1 -> 21 | R34: =R33+(R33*0.0123) -> 20.246 | T34: =T33+1 -> 21 | U34: =U33+(U33*0.0055) -> 20.392797 | W34: =W33+1 -> 21 | X34: =X33+(X33*0.0099) -> 20.198 | Z34: =Z33+1 -> 21 | AA34: =AA33+(AA33*0.02) -> 20.4
N35: =N34+1 -> 22 | O35: =O34+(O34*0.0115) -> 20.462645 | Q35: =Q34+1 -> 22 | R35: =R34+(R34*0.0123) -> 20.495026 | T35: =T34+1 -> 22 | U35: =U34+(U34*0.0055) -> 20.504957 | W35: =W34+1 -> 22 | X35: =X34+(X34*0.0099) -> 20.39796 | Z35: =Z34+1 -> 22 | AA35: =AA34+(AA34*0.02) -> 20.808
A36: Functional Biological Age | N36: =N35+1 -> 23 | O36: =O35+(O35*0.0115) -> 20.697965 | Q36: =Q35+1 -> 23 | R36: =R35+(R35*0.0123) -> 20.747115 | T36: =T35+1 -> 23 | U36: =U35+(U35*0.0055) -> 20.617735 | W36: =W35+1 -> 23 | X36: =X35+(X35*0.0099) -> 20.5999 | Z36: =Z35+1 -> 23 | AA36: =AA35+(AA35*0.02) -> 21.22416
A37: =(B28/100*20)+(B29/100*20)+(B30/100*25)+(B31/100*20)+(B32/100*15) -> 20.070312 | N37: =N36+1 -> 24 | O37: =O36+(O36*0.0115) -> 20.935992 | Q37: =Q36+1 -> 24 | R37: =R36+(R36*0.0123) -> 21.002304 | T37: =T36+1 -> 24 | U37: =U36+(U36*0.0055) -> 20.731132 | W37: =W36+1 -> 24 | X37: =X36+(X36*0.0099) -> 20.803839 | Z37: =Z36+1 -> 24 | AA37: =AA36+(AA36*0.02) -> 21.648643
N38: =N37+1 -> 25 | O38: =O37+(O37*0.0115) -> 21.176756 | Q38: =Q37+1 -> 25 | R38: =R37+(R37*0.0123) -> 21.260632 | T38: =T37+1 -> 25 | U38: =U37+(U37*0.0055) -> 20.845153 | W38: =W37+1 -> 25 | X38: =X37+(X37*0.0099) -> 21.009797 | Z38: =Z37+1 -> 25 | AA38: =AA37+(AA37*0.02) -> 22.081616
N39: =N38+1 -> 26 | O39: =O38+(O38*0.0115) -> 21.420289 | Q39: =Q38+1 -> 26 | R39: =R38+(R38*0.0123) -> 21.522138 | T39: =T38+1 -> 26 | U39: =U38+(U38*0.0055) -> 20.959802 | W39: =W38+1 -> 26 | X39: =X38+(X38*0.0099) -> 21.217794 | Z39: =Z38+1 -> 26 | AA39: =AA38+(AA38*0.02) -> 22.523248
N40: =N39+1 -> 27 | O40: =O39+(O39*0.0115) -> 21.666622 | Q40: =Q39+1 -> 27 | R40: =R39+(R39*0.0123) -> 21.786861 | T40: =T39+1 -> 27 | U40: =U39+(U39*0.0055) -> 21.075081 | W40: =W39+1 -> 27 | X40: =X39+(X39*0.0099) -> 21.42785 | Z40: =Z39+1 -> 27 | AA40: =AA39+(AA39*0.02) -> 22.973713
N41: =N40+1 -> 28 | O41: =O40+(O40*0.0115) -> 21.915788 | Q41: =Q40+1 -> 28 | R41: =R40+(R40*0.0123) -> 22.054839 | T41: =T40+1 -> 28 | U41: =U40+(U40*0.0055) -> 21.190993 | W41: =W40+1 -> 28 | X41: =X40+(X40*0.0099) -> 21.639986 | Z41: =Z40+1 -> 28 | AA41: =AA40+(AA40*0.02) -> 23.433188
B42: Age | C42: Vitality | D42: Age | E42: Strength | F42: Age | G42: Metabolic | H42: Age | I42: Mobility | J42: Age | K42: Cognitive | N42: =N41+1 -> 29 | O42: =O41+(O41*0.0115) -> 22.16782 | Q42: =Q41+1 -> 29 | R42: =R41+(R41*0.0123) -> 22.326113 | T42: =T41+1 -> 29 | U42: =U41+(U41*0.0055) -> 21.307544 | W42: =W41+1 -> 29 | X42: =X41+(X41*0.0099) -> 21.854222 | Z42: =Z41+1 -> 29 | AA42: =AA41+(AA41*0.02) -> 23.901851
B43: =B27 -> 20 | C43: =B28 -> 20 | D43: =B43 -> 20 | E43: =B29 -> 20 | F43: =B27 -> 20 | G43: =B30 -> 20.28125 | H43: =B27 -> 20 | I43: =B31 -> 20 | J43: =B27 -> 20 | K43: =B32 -> 20 | N43: =N42+1 -> 30 | O43: =O42+(O42*0.0115) -> 22.42275 | Q43: =Q42+1 -> 30 | R43: =R42+(R42*0.0123) -> 22.600725 | T43: =T42+1 -> 30 | U43: =U42+(U42*0.0055) -> 21.424735 | W43: =W42+1 -> 30 | X43: =X42+(X42*0.0099) -> 22.070579 | Z43: =Z42+1 -> 30 | AA43: =AA42+(AA42*0.02) -> 24.379888
B44: =C27 -> 30 | C44: =C28 -> 22.3 | D44: =B44 -> 30 | E44: =C29 -> 22.46 | F44: =C27 -> 30 | G44: =C30 -> 21.396719 | H44: =C27 -> 30 | I44: =C31 -> 21.98 | J44: =C27 -> 30 | K44: =C32 -> 24
...

Sheet Persona_1
A1: Persona | B1: Marcus | D1: Metric | F1: 10 Years (49) | G1: 20 Years (59) | H1: 30 Years (69) | I1: 40 Years (79) | M1: Combined Scores
A2: Age | B2: 30 | D2: VO2 max (ml/kg/min) | E2: 42 | F2: =E2+(E2/100*10) -> 46.2 | G2: =F2+(F2/100*10) -> 50.82 | H2: =G2+(G2/100*10) -> 55.902 | I2: =H2+(H2/100*15) -> 64.2873 | L2: Vitality | M2: =B27+ ((1 -((E2 / 43.4) * 0.7 )-((E3/ 100) * 0.3 )) * 100) -> 32.858065
A3: Detail | B3: Marcus works a high-stress finance job but spends his entire weekend mountain biking and playing recreational rugby. He thinks he is fitter than he actually is and relies on youth rather than consistent training to get by. | D3: FEV1 (% predicted) | E3: 98 | F3: =E3-(E3/100*10) -> 88.2 | G3: =F3-(F3/100*10) -> 79.38 | H3: =G3-(G3/100*15) -> 67.473 | I3: =H3-(H3/100*15) -> 57.35205 | L3: Strength | M3: =((J4/100*50)+(J5/100*25)+(J6/100*25)) -> 37 | O3: Functional Biological Age
D4: Grip strength (kg) | E4: 51 | F4: =E4-(E4/100*10) -> 45.9 | G4: =F4-(F4/100*10) -> 41.31 | H4: =G4-(G4/100*6)-(G4/100*6) -> 36.3528 | I4: =H4-((H4/100)*15) -> 30.89988 | J4: =IF(B27<30, FORECAST(E4, OFFSET(Strength_Normative_Data!$A$3, MATCH(E4, Strength_Normative_Data!$B$3:$B$5, 1)-1, 0, 2), OFFSET(Strength_Normative_Data!$B$3, MATCH(E4, Strength_Normative_Data!$B$3:$B$5, 1)-1, 0, 2)), FORECAST(E4, OFFSET(Strength_Normative_Data!$A$5, MATCH(E4, Strength_Normative_Data!$B$5:$B$16, -1)-1, 0, 2), OFFSET(Strength_Normative_Data!$B$5, MATCH(E4, Strength_Normative_Data!$B$5:$B$16, -1)-1, 0, 2))) -> 30 | L4: Metabolic | M4: =B27 - 9*M11 -> 27.457669 | O4: =A37 -> #N/A
D5: STS Power (W/kg) | E5: 3.1 | F5: =E5-(E5/100*12) -> 2.728 | G5: =F5-(F5/100*12) -> 2.40064 | H5: =G5-(G5/100*1.2) - (G5/100* 13.5) -> 2.0477459 | I5: =H5+(H5/100*15) -> 2.3549078 | J5: =FORECAST(E5, OFFSET(Strength_Normative_Data!$O$3, MATCH(E5, Strength_Normative_Data!$P$3:$P$17, -1)-1, 0, 2), OFFSET(Strength_Normative_Data!$P$3, MATCH(E5, Strength_Normative_Data!$P$3:$P$17, -1)-1, 0, 2)) -> 50 | L5: Functional Mobility | M5: =((J14/100*30)+(J15/100*25)+(J16/100*30)+(J17/100*15)) -> #N/A
D6: Vertical jump (cm) | E6: 45 | F6: =E6-(E6/100*12) -> 39.6 | G6: =F6+(F6/100*12) -> 44.352 | H6: =G6+(G6/100*1.2) + (G6/100* 13.5) -> 50.871744 | I6: =H6+(H6/100*15) -> 58.502506 | J6: =FORECAST(E6, OFFSET(Strength_Normative_Data!$J$3, MATCH(E6, Strength_Normative_Data!$K$3:$K$16, -1)-1, 0, 2), OFFSET(Strength_Normative_Data!$K$3, MATCH(E6, Strength_Normative_Data!$K$3:$K$16, -1)-1, 0, 2)) -> 38 | L6: Cognitive | M6: =((J18/100*60)+(J19/100*40)) -> 20
D7: Body fat (%) | E7: 22 | F7: =E7+(E7/100*6) -> 23.32 | G7: =F7+(F7/100*6) -> 24.7192 | H7: =G7+(G7/100*6) -> 26.202352 | I7: =H7+(H7/100*6) -> 27.774493
D8: Waist to height ratio | E8: 0.51 | F8: =E8+(E8/100*4) -> 0.5304 | G8: =F8+(F8/100*4) -> 0.551616 | H8: =G8+(G8/100*4) -> 0.57368064 | I8: =H8+(H8/100*4) -> 0.59662787 | J8: =IF(E8<=0.4,0, IF(E8<=0.5,20*(E8-0.4)/0.1, IF(E8<=0.6,20+40*(E8-0.5)/0.1, 60+40*(MIN(E8,0.75)-0.6)/0.15))) -> 24
D9: Fasting glucose (mmol/L) | E9: 5.4
D10: HbA1c (%) | E10: 5.5 | F10: =E10+(E10/100*5) -> 5.775 | G10: =F10+(F10/100*5) -> 6.06375 | H10: =G10+(G10/100*5) -> 6.3669375 | I10: =H10+(H10/100*5) -> 6.6852844 | J10: =IF(E10<5.7,10*(E10/5.7), IF(E10<6.5,10+40*(E10-5.7)/0.8, 50+50*(MIN(E10,9)-6.5)/2.5)) -> 9.6491228 | L10: Metabolic Index | M10: Metabolic Z score
D11: HOMA IR | E11: 1.8 | F11: =E11+(E11/100*14) -> 2.052 | G11: =F11+(F11/100*14) -> 2.33928 | H11: =G11+(G11/100*14) -> 2.6667792 | I11: =H11+(H11/100*14) -> 3.0401283 | J11: =IF(E11<1.6,10*(E11/1.6), IF(E11<3,10+40*(E11-1.6)/1.4, 50+50*(MIN(E11,7)-3)/4)) -> 15.714286 | L11: =(0.3*K12)+(0.2*J8)+(0.15*J10)+(0.25*J11)+(0.1*J13) -> 20.87594 | M11: =IF(L11<=10,1.5-0.1*L11, IF(L11<=60,0.5-0.02*(L11-10), -0.5-0.03*(L11-60))) -> 0.2824812
D12: ApoB (g/L) | E12: 0.95 | F12: =E12+(E12/100*6) -> 1.007 | G12: =F12+(F12/100*6) -> 1.06742 | H12: =G12+(G12/100*6) -> 1.1314652 | I12: =H12+(H12/100*6) -> 1.1993531 | J12: =E12*100 -> 95 | K12: =IF(J12<80,5*(J12/80), IF(J12<100,10+20*(J12-80)/20, IF(J12<130,30+25*(J12-100)/30, IF(J12<160,55+25*(J12-130)/30, IF(J12<200,80+20*(J12-160)/40,100))))) -> 25
D13: hsCRP (mg/L) | E13: 2.1 | F13: =E13+(E13/100*18) -> 2.478 | G13: =F13+(F13/100*18) -> 2.92404 | H13: =G13+(G13/100*18) -> 3.4503672 | I13: =H13+(H13/100*18) -> 4.0714333 | J13: =IF(E13<1,10*(E13/1), IF(E13<3,10+40*(E13-1)/2, 50+50*(MIN(E13,10)-3)/7)) -> 32
D14: Gait speed (m/s) | E14: 1.4 | F14: =E14-(E14/100*6) -> 1.316 | G14: =F14+(F14/100*6) -> 1.39496 | H14: =G14+(G14/100*7) -> 1.4926072 | I14: =H14+(H14/100*7) -> 1.5970897 | J14: =IFERROR(FORECAST(E14, OFFSET(Mobility_Normative_Data!$A$3, MATCH(E14, Mobility_Normative_Data!$B$3:$B$17, -1)-1, 0, 2), OFFSET(Mobility_Normative_Data!$B$3, MATCH(E14, Mobility_Normative_Data!$B$3:$B$17, -1)-1, 0, 2)), INDEX(Mobility_Normative_Data!$A$3:$A$17, MATCH(E14, Mobility_Normative_Data!$B$3:$B$17, -1))) -> #N/A
D15: Timed Up and Go (sec) | E15: 6.5 | F15: =E15+(E15/100*10) -> 7.15 | G15: =F15+(F15/100*10) -> 7.865 | H15: =G15+(G15/100*10) -> 8.6515 | I15: =H15+(H15/100*10) -> 9.51665 | J15: =FORECAST(E15, OFFSET(Mobility_Normative_Data!$E$3, MATCH(E15, Mobility_Normative_Data!$F$3:$F$18, 1)-1, 0, 2), OFFSET(Mobility_Normative_Data!$F$3, MATCH(E15, Mobility_Normative_Data!$F$3:$F$18, 1)-1, 0, 2)) -> 45
D16: Single leg stance (sec) | E16: 45 | F16: =E16-(E16/100*20) -> 36 | G16: =F16+(F16/100*20) -> 43.2 | H16: =G16+(G16/100*20) -> 51.84 | I16: =H16+(H16/100*20) -> 62.208 | J16: =FORECAST(E16, OFFSET(Mobility_Normative_Data!$I$3, MATCH(E16, Mobility_Normative_Data!$J$3:$J$17, -1)-1, 0, 2), OFFSET(Mobility_Normative_Data!$J$3, MATCH(E16, Mobility_Normative_Data!$J$3:$J$17, -1)-1, 0, 2)) -> 20
D17: Sit and reach (cm) | E17: 36 | F17: =E17-(E17/100*10) -> 32.4 | G17: =F17+(F17/100*10) -> 35.64 | H17: =G17+(G17/100*10) -> 39.204 | I17: =H17+(H17/100*10) -> 43.1244 | J17: =FORECAST(E17, OFFSET(Mobility_Normative_Data!$M$3, MATCH(E17, Mobility_Normative_Data!$N$3:$N$17, -1)-1, 0, 2), OFFSET(Mobility_Normative_Data!$N$3, MATCH(E17, Mobility_Normative_Data!$N$3:$N$17, -1)-1, 0, 2)) -> 35
D18: Processing speed (SD) | E18: 0.5 | F18: =E18 +(-0.2) -> 0.3 | G18: =F18 +(-0.2) -> 0.1 | H18: =G18 +(-0.3) -> -0.2 | I18: =H18 +(-0.3) -> -0.5 | J18: =MAX(18,B27-(E18*25)) -> 18
D19: Working memory (SD) | E19: 0.2 | F19: =E19+(-0.2) -> 0 | G19: =F19 +(-0.2) -> -0.2 | H19: =G19 +(-0.3) -> -0.5 | I19: =H19 +(-0.3) -> -0.8 | J19: =MAX(18,B27-(E19*35)) -> 23
A23: Overall Decline predicitons
B25: Present | C25: 10 years time | D25: 20 Years time | E25: Thirty years | F25: 40 years | N25: Graphing
A26: Sex | B26: Male | N26: Chronological Age | O26: Vitality Decline | Q26: Chronological Age | R26: Strength Decline | T26: Chronological Age | U26: Metabolic Decline | W26: Chronological Age | X26: Mobility Decline | Z26: Chronological Age | AA26: Cognitive Decline
A27: Chronological | B27: =B2 -> 30 | C27: =B27+10 -> 40 | D27: =C27+10 -> 50 | E27: =D27+10 -> 60 | F27: =E27+10 -> 70 | N27: =B27 -> 30 | O27: =M2 -> 32.858065 | Q27: =N27 -> 30 | R27: =M3 -> 37 | T27: =N27 -> 30 | U27: =M4 -> 27.457669 | W27: =N27 -> 30 | X27: =M5 -> #N/A | Z27: =N27 -> 30 | AA27: =M6 -> 20
A28: Vitality | B28: =M2 -> 32.858065 | C28: =B28+(B28/100*11.5) -> 36.636742 | D28: =C28+(C28/100*32.2) -> 48.433773 | E28: =D28+(D28/100*32.2) -> 64.029448 | F28: =E28+(E28/100*32.2) -> 84.64693 | N28: =N27+1 -> 31 | O28: =O27+(O27*0.0115) -> 33.235932 | Q28: =Q27+1 -> 31 | R28: =R27+(R27*0.0123) -> 37.4551 | T28: =T27+1 -> 31 | U28: =U27+(U27*0.011) -> 27.759704 | W28: =W27+1 -> 31 | X28: =X27+(X27*0.0099) -> #N/A | Z28: =Z27+1 -> 31 | AA28: =AA27+(AA27*0.02) -> 20.4
A29: Strength | B29: =M3 -> 37 | C29: =B29+(B29/100*12.3) -> 41.551 | D29: =C29+(C29/100*30.8) -> 54.348708 | E29: =D29+(D29/100*30.8) -> 71.08811 | F29: =E29+(E29/100*30.8) -> 92.983248 | N29: =N28+1 -> 32 | O29: =O28+(O28*0.0115) -> 33.618145 | Q29: =Q28+1 -> 32 | R29: =R28+(R28*0.0123) -> 37.915798 | T29: =T28+1 -> 32 | U29: =U28+(U28*0.011) -> 28.06506 | W29: =W28+1 -> 32 | X29: =X28+(X28*0.0099) -> #N/A | Z29: =Z28+1 -> 32 | AA29: =AA28+(AA28*0.02) -> 20.808
A30: Metabolic | B30: =M4 -> 27.457669 | C30: =B30+(B30/100*5.5) -> 28.967841 | D30: =C30+(C30/100*11) -> 32.154303 | E30: =D30+(D30/100*11) -> 35.691277 | F30: =E30+(E30/100*11) -> 39.617317 | N30: =N29+1 -> 33 | O30: =O29+(O29*0.0115) -> 34.004754 | Q30: =Q29+1 -> 33 | R30: =R29+(R29*0.0123) -> 38.382162 | T30: =T29+1 -> 33 | U30: =U29+(U29*0.011) -> 28.373776 | W30: =W29+1 -> 33 | X30: =X29+(X29*0.0099) -> #N/A | Z30: =Z29+1 -> 33 | AA30: =AA29+(AA29*0.02) -> 21.22416
A31: Mobility | B31: =M5 -> #N/A | C31: =B31+(B31/100*9.9) -> #N/A | D31: =C31+(C31/100*19.8) -> #N/A | E31: =D31+(D31/100*19.8) -> #N/A | F31: =E31+(E31/100*19.8) -> #N/A | N31: =N30+1 -> 34 | O31: =O30+(O30*0.0115) -> 34.395809 | Q31: =Q30+1 -> 34 | R31: =R30+(R30*0.0123) -> 38.854263 | T31: =T30+1 -> 34 | U31: =U30+(U30*0.011) -> 28.685887 | W31: =W30+1 -> 34 | X31: =X30+(X30*0.0099) -> #N/A | Z31: =Z30+1 -> 34 | AA31: =AA30+(AA30*0.02) -> 21.648643
A32: Cognitive | B32: =M6 -> 20 | C32: =B32+(B32/100*20) -> 24 | D32: =C32+(C32/100*60) -> 38.4 | E32: =D32+(D32/100*60) -> 61.44 | F32: =E32+(E32/100*60) -> 98.304 | N32: =N31+1 -> 35 | O32: =O31+(O31*0.0115) -> 34.791361 | Q32: =Q31+1 -> 35 | R32: =R31+(R31*0.0123) -> 39.33217 | T32: =T31+1 -> 35 | U32: =U31+(U31*0.011) -> 29.001432 | W32: =W31+1 -> 35 | X32: =X31+(X31*0.0099) -> #N/A | Z32: =Z31+1 -> 35 | AA32: =AA31+(AA31*0.02) -> 22.081616
N33: =N32+1 -> 36 | O33: =O32+(O32*0.0115) -> 35.191461 | Q33: =Q32+1 -> 36 | R33: =R32+(R32*0.0123) -> 39.815956 | T33: =T32+1 -> 36 | U33: =U32+(U32*0.011) -> 29.320448 | W33: =W32+1 -> 36 | X33: =X32+(X32*0.0099) -> #N/A | Z33: =Z32+1 -> 36 | AA33: =AA32+(AA32*0.02) -> 22.523248
N34: =N33+1 -> 37 | O34: =O33+(O33*0.0115) -> 35.596163 | Q34: =Q33+1 -> 37 | R34: =R33+(R33*0.0123) -> 40.305692 | T34: =T33+1 -> 37 | U34: =U33+(U33*0.011) -> 29.642973 | W34: =W33+1 -> 37 | X34: =X33+(X33*0.0099) -> #N/A | Z34: =Z33+1 -> 37 | AA34: =AA33+(AA33*0.02) -> 22.973713
N35: =N34+1 -> 38 | O35: =O34+(O34*0.0115) -> 36.005519 | Q35: =Q34+1 -> 38 | R35: =R34+(R34*0.0123) -> 40.801452 | T35: =T34+1 -> 38 | U35: =U34+(U34*0.011) -> 29.969046 | W35: =W34+1 -> 38 | X35: =X34+(X34*0.0099) -> #N/A | Z35: =Z34+1 -> 38 | AA35: =AA34+(AA34*0.02) -> 23.433188
A36: Functional Biological Age | N36: =N35+1 -> 39 | O36: =O35+(O35*0.0115) -> 36.419582 | Q36: =Q35+1 -> 39 | R36: =R35+(R35*0.0123) -> 41.30331 | T36: =T35+1 -> 39 | U36: =U35+(U35*0.011) -> 30.298705 | W36: =W35+1 -> 39 | X36: =X35+(X35*0.0099) -> #N/A | Z36: =Z35+1 -> 39 | AA36: =AA35+(AA35*0.02) -> 23.901851
A37: =(B28/100*20)+(B29/100*20)+(B30/100*25)+(B31/100*20)+(B32/100*15) -> #N/A | N37: =N36+1 -> 40 | O37: =O36+(O36*0.0115) -> 36.838408 | Q37: =Q36+1 -> 40 | R37: =R36+(R36*0.0123) -> 41.811341 | T37: =T36+1 -> 40 | U37: =U36+(U36*0.011) -> 30.631991 | W37: =W36+1 -> 40 | X37: =X36+(X36*0.0099) -> #N/A | Z37: =Z36+1 -> 40 | AA37: =AA36+(AA36*0.02) -> 24.379888
B42: Age | C42: Vitality | D42: Age | E42: Strength | F42: Age | G42: Metabolic | H42: Age | I42: Mobility | J42: Age | K42: Cognitive
B43: =B27 -> 30 | C43: =B28 -> 32.858065 | D43: =B43 -> 30 | E43: =B29 -> 37 | F43: =B27 -> 30 | G43: =B30 -> 27.457669 | H43: =B27 -> 30 | I43: =B31 -> #N/A | J43: =B27 -> 30 | K43: =B32 -> 20
B44: =C27 -> 40 | C44: =C28 -> 36.636742 | D44: =B44 -> 40 | E44: =C29 -> 41.551 | F44: =C27 -> 40 | G44: =C30 -> 28.967841 | H44: =C27 -> 40 | I44: =C31 -> #N/A | J44: =C27 -> 40 | K44: =C32 -> 24
B45: =D27 -> 50 | C45: =D28 -> 48.433773 | D45: =D27 -> 50 | E45: =D29 -> 54.348708 | F45: =D27 -> 50 | G45: =D30 -> 32.154303 | H45: =D27 -> 50 | I45: =D31 -> #N/A | J45: =D27 -> 50 | K45: =D32 -> 38.4
B46: =E27 -> 60 | C46: =E28 -> 64.029448 | D46: =E27 -> 60 | E46: =E29 -> 71.08811 | F46: =E27 -> 60 | G46: =E30 -> 35.691277 | H46: =E27 -> 60 | I46: =E31 -> #N/A | J46: =E27 -> 60 | K46: =E32 -> 61.44
B47: =F27 -> 70 | C47: =F28 -> 84.64693 | D47: =F27 -> 70 | E47: =F29 -> 92.983248 | F47: =F27 -> 70 | G47: =F31 -> #N/A | H47: =F27 -> 70 | I47: =F31 -> #N/A | J47: =F27 -> 70 | K47: =F32 -> 98.304

Sheet Persona_2
A1: Persona | B1: Elena | D1: Metric | F1: 10 Years (49) | G1: 20 Years (59) | H1: 30 Years (69) | I1: 40 Years (79) | M1: Combined Scores
A2: Age | B2: 50 | D2: VO2 max (ml/kg/min) | E2: 48 | F2: =E2+(E2/100*10) -> 52.8 | G2: =F2+(F2/100*10) -> 58.08 | H2: =G2+(G2/100*10) -> 63.888 | I2: =H2+(H2/100*15) -> 73.4712 | L2: Vitality | M2: =B27+ ((1 -((E2 / 26.6) * 0.7 )-((E3/ 100) * 0.3 )) * 100) -> -6.0157895
A3: Detail | B3: Elena is a former competitive marathon runner who now focuses on swimming and yoga. She is incredibly disciplined with her diet but has noticed a loss of explosive power as she enters menopause. | D3: FEV1 (% predicted) | E3: 99 | F3: =E3-(E3/100*10) -> 89.1 | G3: =F3-(F3/100*10) -> 80.19 | H3: =G3-(G3/100*15) -> 68.1615 | I3: =H3-(H3/100*15) -> 57.937275 | L3: Strength | M3: =((J4/100*50)+(J5/100*25)+(J6/100*25)) -> 53.666667 | O3: Functional Biological Age
D4: Grip strength (kg) | E4: 28 | F4: =E4+(E4/100*10) -> 30.8 | G4: =F4+(F4/100*10) -> 33.88 | H4: =G4+(G4/100*6)+(G4/100*6) -> 37.9456 | I4: =H4+((H4/100)*15) -> 43.63744 | J4: =IF(B27<30, FORECAST(E4, OFFSET(Strength_Normative_Data!$A$3, MATCH(E4, Strength_Normative_Data!$C$3:$C$5, 1)-1, 0, 2), OFFSET(Strength_Normative_Data!$C$3, MATCH(E4, Strength_Normative_Data!$C$3:$C$5, 1)-1, 0, 2)), FORECAST(E4, OFFSET(Strength_Normative_Data!$A$5, MATCH(E4, Strength_Normative_Data!$C$5:$C$16, -1)-1, 0, 2), OFFSET(Strength_Normative_Data!$C$5, MATCH(E4, Strength_Normative_Data!$C$5:$C$16, -1)-1, 0, 2))) -> 50 | L4: Metabolic | M4: =B27 - 9*M11 -> 40.962401 | O4: =A37 -> 31.979347
D5: STS Power (W/kg) | E5: 2.2 | F5: =E5+(E5/100*12) -> 2.464 | G5: =F5+(F5/100*12) -> 2.75968 | H5: =G5+(G5/100*1.2) + (G5/100* 13.5) -> 3.165353 | I5: =H5+(H5/100*15) -> 3.6401559 | J5: =FORECAST(E5, OFFSET(Strength_Normative_Data!$O$3, MATCH(E5, Strength_Normative_Data!$Q$3:$Q$17, -1)-1, 0, 2), OFFSET(Strength_Normative_Data!$Q$3, MATCH(E5, Strength_Normative_Data!$Q$3:$Q$17, -1)-1, 0, 2)) -> 56.666667 | L5: Functional Mobility | M5: =((J14/100*30)+(J15/100*25)+(J16/100*30)+(J17/100*15)) -> 44.392857
D6: Vertical jump (cm) | E6: 20 | F6: =E6+(E6/100*12) -> 22.4 | G6: =F6+(F6/100*12) -> 25.088 | H6: =G6+(G6/100*1.2) + (G6/100* 13.5) -> 28.775936 | I6: =H6+(H6/100*15) -> 33.092326 | J6: =FORECAST(E6, OFFSET(Strength_Normative_Data!$J$3, MATCH(E6, Strength_Normative_Data!$L$3:$L$16, -1)-1, 0, 2), OFFSET(Strength_Normative_Data!$L$3, MATCH(E6, Strength_Normative_Data!$L$3:$L$16, -1)-1, 0, 2)) -> 58 | L6: Cognitive | M6: =((J18/100*60)+(J19/100*40)) -> 22.2
D7: Body fat (%) | E7: 19 | F7: =E7+(E7/100*6) -> 20.14 | G7: =F7+(F7/100*6) -> 21.3484 | H7: =G7+(G7/100*6) -> 22.629304 | I7: =H7+(H7/100*6) -> 23.987062
D8: Waist to height ratio | E8: 0.42 | F8: =E8+(E8/100*4) -> 0.4368 | G8: =F8+(F8/100*4) -> 0.454272 | H8: =G8+(G8/100*4) -> 0.47244288 | I8: =H8+(H8/100*4) -> 0.4913406 | J8: =IF(E8<=0.4,0, IF(E8<=0.5,20*(E8-0.4)/0.1, IF(E8<=0.6,20+40*(E8-0.5)/0.1, 60+40*(MIN(E8,0.75)-0.6)/0.15))) -> 4
D9: Fasting glucose (mmol/L) | E9: 4.6
D10: HbA1c (%) | E10: 4.9 | F10: =E10+(E10/100*5) -> 5.145 | G10: =F10+(F10/100*5) -> 5.40225 | H10: =G10+(G10/100*5) -> 5.6723625 | I10: =H10+(H10/100*5) -> 5.9559806 | J10: =IF(E10<5.7,10*(E10/5.7), IF(E10<6.5,10+40*(E10-5.7)/0.8, 50+50*(MIN(E10,9)-6.5)/2.5)) -> 8.5964912 | L10: Metabolic Index | M10: Metabolic Z score
D11: HOMA IR | E11: 0.8 | F11: =E11+(E11/100*14) -> 0.912 | G11: =F11+(F11/100*14) -> 1.03968 | H11: =G11+(G11/100*14) -> 1.1852352 | I11: =H11+(H11/100*14) -> 1.3511681 | J11: =IF(E11<1.6,10*(E11/1.6), IF(E11<3,10+40*(E11-1.6)/1.4, 50+50*(MIN(E11,7)-3)/4)) -> 5 | L11: =(0.3*K12)+(0.2*J8)+(0.15*J10)+(0.25*J11)+(0.1*J13) -> 4.9582237 | M11: =IF(L11<=10,1.5-0.1*L11, IF(L11<=60,0.5-0.02*(L11-10), -0.5-0.03*(L11-60))) -> 1.0041776
D12: ApoB (g/L) | E12: 0.65 | F12: =E12+(E12/100*6) -> 0.689 | G12: =F12+(F12/100*6) -> 0.73034 | H12: =G12+(G12/100*6) -> 0.7741604 | I12: =H12+(H12/100*6) -> 0.82061002 | J12: =E12*100 -> 65 | K12: =IF(J12<80,5*(J12/80), IF(J12<100,10+20*(J12-80)/20, IF(J12<130,30+25*(J12-100)/30, IF(J12<160,55+25*(J12-130)/30, IF(J12<200,80+20*(J12-160)/40,100))))) -> 4.0625
D13: hsCRP (mg/L) | E13: 0.4 | F13: =E13+(E13/100*18) -> 0.472 | G13: =F13+(F13/100*18) -> 0.55696 | H13: =G13+(G13/100*18) -> 0.6572128 | I13: =H13+(H13/100*18) -> 0.7755111 | J13: =IF(E13<1,10*(E13/1), IF(E13<3,10+40*(E13-1)/2, 50+50*(MIN(E13,10)-3)/7)) -> 4
D14: Gait speed (m/s) | E14: 1.3 | F14: =E14-(E14/100*6) -> 1.222 | G14: =F14+(F14/100*6) -> 1.29532 | H14: =G14+(G14/100*7) -> 1.3859924 | I14: =H14+(H14/100*7) -> 1.4830119 | J14: =IFERROR(FORECAST(E14, OFFSET(Mobility_Normative_Data!$A$3, MATCH(E14, Mobility_Normative_Data!$B$3:$B$17, -1)-1, 0, 2), OFFSET(Mobility_Normative_Data!$B$3, MATCH(E14, Mobility_Normative_Data!$B$3:$B$17, -1)-1, 0, 2)), INDEX(Mobility_Normative_Data!$A$3:$A$17, MATCH(E14, Mobility_Normative_Data!$B$3:$B$17, -1))) -> 67.142857
D15: Timed Up and Go (sec) | E15: 7.8 | F15: =E15+(E15/100*10) -> 8.58 | G15: =F15+(F15/100*10) -> 9.438 | H15: =G15+(G15/100*10) -> 10.3818 | I15: =H15+(H15/100*10) -> 11.41998 | J15: =FORECAST(E15, OFFSET(Mobility_Normative_Data!$E$3, MATCH(E15, Mobility_Normative_Data!$F$3:$F$18, 1)-1, 0, 2), OFFSET(Mobility_Normative_Data!$F$3, MATCH(E15, Mobility_Normative_Data!$F$3:$F$18, 1)-1, 0, 2)) -> 58
D16: Single leg stance (sec) | E16: 45 | F16: =E16-(E16/100*20) -> 36 | G16: =F16+(F16/100*20) -> 43.2 | H16: =G16+(G16/100*20) -> 51.84 | I16: =H16+(H16/100*20) -> 62.208 | J16: =FORECAST(E16, OFFSET(Mobility_Normative_Data!$I$3, MATCH(E16, Mobility_Normative_Data!$J$3:$J$17, -1)-1, 0, 2), OFFSET(Mobility_Normative_Data!$J$3, MATCH(E16, Mobility_Normative_Data!$J$3:$J$17, -1)-1, 0, 2)) -> 20
D17: Sit and reach (cm) | E17: 38 | F17: =E17-(E17/100*10) -> 34.2 | G17: =F17+(F17/100*10) -> 37.62 | H17: =G17+(G17/100*10) -> 41.382 | I17: =H17+(H17/100*10) -> 45.5202 | J17: =FORECAST(E17, OFFSET(Mobility_Normative_Data!$M$3, MATCH(E17, Mobility_Normative_Data!$N$3:$N$17, -1)-1, 0, 2), OFFSET(Mobility_Normative_Data!$N$3, MATCH(E17, Mobility_Normative_Data!$N$3:$N$17, -1)-1, 0, 2)) -> 25
D18: Processing speed (SD) | E18: 1 | F18: =E18 +(-0.2) -> 0.8 | G18: =F18 +(-0.2) -> 0.6 | H18: =G18 +(-0.3) -> 0.3 | I18: =H18 +(-0.3) -> 0 | J18: =MAX(18,B27-(E18*25)) -> 25
D19: Working memory (SD) | E19: 1.2 | F19: =E19+(-0.2) -> 1 | G19: =F19 +(-0.2) -> 0.8 | H19: =G19 +(-0.3) -> 0.5 | I19: =H19 +(-0.3) -> 0.2 | J19: =MAX(18,B27-(E19*35)) -> 18
A23: Overall Decline predicitons
B25: Present | C25: 10 years time | D25: 20 Years time | E25: Thirty years | F25: 40 years
A26: Sex | B26: Male
A27: Chronological | B27: =B2 -> 50 | C27: =B27+10 -> 60 | D27: =C27+10 -> 70 | E27: =D27+10 -> 80 | F27: =E27+10 -> 90
A28: Vitality | B28: =M2 -> -6.0157895 | C28: =B28+(B28/100*11.5) -> -6.7076053 | D28: =C28+(C28/100*32.2) -> -8.8674542 | E28: =D28+(D28/100*32.2) -> -11.722774 | F28: =E28+(E28/100*32.2) -> -15.497508
A29: Strength | B29: =M3 -> 53.666667 | C29: =B29+(B29/100*12.3) -> 60.267667 | D29: =C29+(C29/100*30.8) -> 78.830108 | E29: =D29+(D29/100*30.8) -> 103.10978 | F29: =E29+(E29/100*30.8) -> 134.86759
A30: Metabolic | B30: =M4 -> 40.962401 | C30: =B30+(B30/100*5.5) -> 43.215333 | D30: =C30+(C30/100*11) -> 47.96902 | E30: =D30+(D30/100*11) -> 53.245612 | F30: =E30+(E30/100*11) -> 59.10263
A31: Mobility | B31: =M5 -> 44.392857 | C31: =B31+(B31/100*9.9) -> 48.78775 | D31: =C31+(C31/100*19.8) -> 58.447725 | E31: =D31+(D31/100*19.8) -> 70.020374 | F31: =E31+(E31/100*19.8) -> 83.884408
A32: Cognitive | B32: =M6 -> 22.2 | C32: =B32+(B32/100*20) -> 26.64 | D32: =C32+(C32/100*60) -> 42.624 | E32: =D32+(D32/100*60) -> 68.1984 | F32: =E32+(E32/100*60) -> 109.11744
M35: Chronological Age | N35: Vitality Decline | P35: Chronological Age | Q35: Strength Decline | S35: Chronological Age | T35: Metabolic Decline | V35: Chronological Age | W35: Mobility Decline | Y35: Chronological Age | Z35: Cognitive Decline
A36: Functional Biological Age | M36: =B27 -> 50 | N36: =M2 -> -6.0157895 | P36: =M36 -> 50 | Q36: =M3 -> 53.666667 | S36: =M36 -> 50 | T36: =M4 -> 40.962401 | V36: =M36 -> 50 | W36: =M5 -> 44.392857 | Y36: =M36 -> 50 | Z36: =M6 -> 22.2
A37: =(B28/100*20)+(B29/100*20)+(B30/100*25)+(B31/100*20)+(B32/100*15) -> 31.979347 | M37: =M36+1 -> 51 | N37: =N36-(N36*0.0115) -> -5.9466079 | P37: =P36+1 -> 51 | Q37: =Q36+(Q36*0.0123) -> 54.326767 | S37: =S36+1 -> 51 | T37: =T36+(T36*0.011) -> 41.412988 | V37: =V36+1 -> 51 | W37: =W36+(W36*0.0099) -> 44.832346 | Y37: =Y36+1 -> 51 | Z37: =Z36+(Z36*0.02) -> 22.644
M38: =M37+1 -> 52 | N38: =N37-(N37*0.0115) -> -5.8782219 | P38: =P37+1 -> 52 | Q38: =Q37+(Q37*0.0123) -> 54.994986 | S38: =S37+1 -> 52 | T38: =T37+(T37*0.011) -> 41.868531 | V38: =V37+1 -> 52 | W38: =W37+(W37*0.0099) -> 45.276187 | Y38: =Y37+1 -> 52 | Z38: =Z37+(Z37*0.02) -> 23.09688
M39: =M38+1 -> 53 | N39: =N38-(N38*0.0115) -> -5.8106224 | P39: =P38+1 -> 53 | Q39: =Q38+(Q38*0.0123) -> 55.671424 | S39: =S38+1 -> 53 | T39: =T38+(T38*0.011) -> 42.329084 | V39: =V38+1 -> 53 | W39: =W38+(W38*0.0099) -> 45.724421 | Y39: =Y38+1 -> 53 | Z39: =Z38+(Z38*0.02) -> 23.558818
M40: =M39+1 -> 54 | N40: =N39-(N39*0.0115) -> -5.7438002 | P40: =P39+1 -> 54 | Q40: =Q39+(Q39*0.0123) -> 56.356183 | S40: =S39+1 -> 54 | T40: =T39+(T39*0.011) -> 42.794704 | V40: =V39+1 -> 54 | W40: =W39+(W39*0.0099) -> 46.177093 | Y40: =Y39+1 -> 54 | Z40: =Z39+(Z39*0.02) -> 24.029994
M41: =M40+1 -> 55 | N41: =N40-(N40*0.0115) -> -5.6777465 | P41: =P40+1 -> 55 | Q41: =Q40+(Q40*0.0123) -> 57.049364 | S41: =S40+1 -> 55 | T41: =T40+(T40*0.011) -> 43.265446 | V41: =V40+1 -> 55 | W41: =W40+(W40*0.0099) -> 46.634246 | Y41: =Y40+1 -> 55 | Z41: =Z40+(Z40*0.02) -> 24.510594
B42: Age | C42: Vitality | D42: Age | E42: Strength | F42: Age | G42: Metabolic | H42: Age | I42: Mobility | J42: Age | K42: Cognitive | M42: =M41+1 -> 56 | N42: =N41-(N41*0.0115) -> -5.6124524 | P42: =P41+1 -> 56 | Q42: =Q41+(Q41*0.0123) -> 57.751071 | S42: =S41+1 -> 56 | T42: =T41+(T41*0.011) -> 43.741366 | V42: =V41+1 -> 56 | W42: =W41+(W41*0.0099) -> 47.095925 | Y42: =Y41+1 -> 56 | Z42: =Z41+(Z41*0.02) -> 25.000806
B43: =B27 -> 50 | C43: =B28 -> -6.0157895 | D43: =B43 -> 50 | E43: =B29 -> 53.666667 | F43: =B27 -> 50 | G43: =B30 -> 40.962401 | H43: =B27 -> 50 | I43: =B31 -> 44.392857 | J43: =B27 -> 50 | K43: =B32 -> 22.2 | M43: =M42+1 -> 57 | N43: =N42-(N42*0.0115) -> -5.5479092 | P43: =P42+1 -> 57 | Q43: =Q42+(Q42*0.0123) -> 58.461409 | S43: =S42+1 -> 57 | T43: =T42+(T42*0.011) -> 44.222521 | V43: =V42+1 -> 57 | W43: =W42+(W42*0.0099) -> 47.562175 | Y43: =Y42+1 -> 57 | Z43: =Z42+(Z42*0.02) -> 25.500822
B44: =C27 -> 60 | C44: =C28 -> -6.7076053 | D44: =B44 -> 60 | E44: =C29 -> 60.267667 | F44: =C27 -> 60 | G44: =C30 -> 43.215333 | H44: =C27 -> 60 | I44: =C31 -> 48.78775 | J44: =C27 -> 60 | K44: =C32 -> 26.64 | M44: =M43+1 -> 58 | N44: =N43-(N43*0.0115) -> -5.4841082 | P44: =P43+1 -> 58 | Q44: =Q43+(Q43*0.0123) -> 59.180484 | S44: =S43+1 -> 58 | T44: =T43+(T43*0.011) -> 44.708969 | V44: =V43+1 -> 58 | W44: =W43+(W43*0.0099) -> 48.03304 | Y44: =Y43+1 -> 58 | Z44: =Z43+(Z43*0.02) -> 26.010838
B45: =D27 -> 70 | C45: =D28 -> -8.8674542 | D45: =D27 -> 70 | E45: =D29 -> 78.830108 | F45: =D27 -> 70 | G45: =D30 -> 47.96902 | H45: =D27 -> 70 | I45: =D31 -> 58.447725 | J45: =D27 -> 70 | K45: =D32 -> 42.624 | M45: =M44+1 -> 59 | N45: =N44-(N44*0.0115) -> -5.421041 | P45: =P44+1 -> 59 | Q45: =Q44+(Q44*0.0123) -> 59.908404 | S45: =S44+1 -> 59 | T45: =T44+(T44*0.011) -> 45.200767 | V45: =V44+1 -> 59 | W45: =W44+(W44*0.0099) -> 48.508567 | Y45: =Y44+1 -> 59 | Z45: =Z44+(Z44*0.02) -> 26.531055
B46: =E27 -> 80 | C46: =E28 -> -11.722774 | D46: =E27 -> 80 | E46: =E29 -> 103.10978 | F46: =E27 -> 80 | G46: =E30 -> 53.245612 | H46: =E27 -> 80 | I46: =E31 -> 70.020374 | J46: =E27 -> 80 | K46: =E32 -> 68.1984 | M46: =M45+1 -> 60 | N46: =N45-(N45*0.0115) -> -5.358699 | P46: =P45+1 -> 60 | Q46: =Q45+(Q45*0.0123) -> 60.645278 | S46: =S45+1 -> 60 | T46: =T45+(T45*0.011) -> 45.697976 | V46: =V45+1 -> 60 | W46: =W45+(W45*0.0099) -> 48.988802 | Y46: =Y45+1 -> 60 | Z46: =Z45+(Z45*0.02) -> 27.061676
...

Sheet Persona_3
A1: Persona | B1: Jayden | D1: Metric | F1: 10 Years (49) | G1: 20 Years (59) | H1: 30 Years (69) | I1: 40 Years (79) | M1: Combined Scores
A2: Age | B2: 24 | D2: VO2 max (ml/kg/min) | E2: 31 | F2: =E2+(E2/100*10) -> 34.1 | G2: =F2+(F2/100*10) -> 37.51 | H2: =G2+(G2/100*10) -> 41.261 | I2: =H2+(H2/100*15) -> 47.45015 | L2: Vitality | M2: =B27+ ((1 -((E2 / 48) * 0.7 )-((E3/ 100) * 0.3 )) *100) -> 52.391667
A3: Detail | B3: Jayden is a professional e-sports player. While his cognitive reaction times are elite, he survives on energy drinks and fast food, rarely leaving his chair for physical activity. | D3: FEV1 (% predicted) | E3: 88 | F3: =E3-(E3/100*10) -> 79.2 | G3: =F3-(F3/100*10) -> 71.28 | H3: =G3-(G3/100*15) -> 60.588 | I3: =H3-(H3/100*15) -> 51.4998 | L3: Strength | M3: =((J4/100*50)+(J5/100*25)+(J6/100*25)) -> 78.928571 | O3: Functional Biological Age
D4: Grip strength (kg) | E4: 36 | F4: =E4+(E4/100*10) -> 39.6 | G4: =F4+(F4/100*10) -> 43.56 | H4: =G4+(G4/100*6)+(G4/100*6) -> 48.7872 | I4: =H4+((H4/100)*15) -> 56.10528 | J4: =IFERROR( IF(B27<30, FORECAST(E4, OFFSET(Strength_Normative_Data!$A$3, MATCH(E4, Strength_Normative_Data!$B$3:$B$5, 1)-1, 0, 2), OFFSET(Strength_Normative_Data!$B$3, MATCH(E4, Strength_Normative_Data!$B$3:$B$5, 1)-1, 0, 2)), FORECAST(E4, OFFSET(Strength_Normative_Data!$A$5, MATCH(E4, Strength_Normative_Data!$B$5:$B$16, -1)-1, 0, 2), OFFSET(Strength_Normative_Data!$B$5, MATCH(E4, Strength_Normative_Data!$B$5:$B$16, -1)-1, 0, 2)) ), IF(E4 > MAX(Strength_Normative_Data!$B$3:$B$16), 20, 85) ) -> 85 | L4: Metabolic | M4: =B27 - 9*M11 -> 25.132714 | O4: =A37 -> 48.847226
D5: STS Power (W/kg) | E5: 1.9 | F5: =E5+(E5/100*12) -> 2.128 | G5: =F5+(F5/100*12) -> 2.38336 | H5: =G5+(G5/100*1.2) + (G5/100* 13.5) -> 2.7337139 | I5: =H5+(H5/100*15) -> 3.143771 | J5: =FORECAST(E5, OFFSET(Strength_Normative_Data!$O$3, MATCH(E5, Strength_Normative_Data!$P$3:$P$17, -1)-1, 0, 2), OFFSET(Strength_Normative_Data!$P$3, MATCH(E5, Strength_Normative_Data!$P$3:$P$17, -1)-1, 0, 2)) -> 80 | L5: Functional Mobility | M5: =((J14/100*30)+(J15/100*25)+(J16/100*30)+(J17/100*15)) -> 68 | T5: h
D6: Vertical jump (cm) | E6: 28 | F6: =E6+(E6/100*12) -> 31.36 | G6: =F6+(F6/100*12) -> 35.1232 | H6: =G6+(G6/100*1.2) + (G6/100* 13.5) -> 40.28631 | I6: =H6+(H6/100*15) -> 46.329257 | J6: =FORECAST(E6, OFFSET(Strength_Normative_Data!$J$3, MATCH(E6, Strength_Normative_Data!$K$3:$K$16, -1)-1, 0, 2), OFFSET(Strength_Normative_Data!$K$3, MATCH(E6, Strength_Normative_Data!$K$3:$K$16, -1)-1, 0, 2)) -> 65.714286 | L6: Cognitive | M6: =((J18/100*60)+(J19/100*40)) -> 18
D7: Body fat (%) | E7: 28 | F7: =E7+(E7/100*6) -> 29.68 | G7: =F7+(F7/100*6) -> 31.4608 | H7: =G7+(G7/100*6) -> 33.348448 | I7: =H7+(H7/100*6) -> 35.349355
D8: Waist to height ratio | E8: 0.58 | F8: =E8+(E8/100*4) -> 0.6032 | G8: =F8+(F8/100*4) -> 0.627328 | H8: =G8+(G8/100*4) -> 0.65242112 | I8: =H8+(H8/100*4) -> 0.67851796 | J8: =IF(E8<=0.4,0, IF(E8<=0.5,20*(E8-0.4)/0.1, IF(E8<=0.6,20+40*(E8-0.5)/0.1, 60+40*(MIN(E8,0.75)-0.6)/0.15))) -> 52
D9: Fasting glucose (mmol/L) | E9: 5.9
D10: HbA1c (%) | E10: 5.8 | F10: =E10+(E10/100*5) -> 6.09 | G10: =F10+(F10/100*5) -> 6.3945 | H10: =G10+(G10/100*5) -> 6.714225 | I10: =H10+(H10/100*5) -> 7.0499363 | J10: =IF(E10<5.7,10*(E10/5.7), IF(E10<6.5,10+40*(E10-5.7)/0.8, 50+50*(MIN(E10,9)-6.5)/2.5)) -> 15 | L10: Metabolic Index | M10: Metabolic Z score
D11: HOMA IR | E11: 2.9 | F11: =E11+(E11/100*14) -> 3.306 | G11: =F11+(F11/100*14) -> 3.76884 | H11: =G11+(G11/100*14) -> 4.2964776 | I11: =H11+(H11/100*14) -> 4.8979845 | J11: =IF(E11<1.6,10*(E11/1.6), IF(E11<3,10+40*(E11-1.6)/1.4, 50+50*(MIN(E11,7)-3)/4)) -> 47.142857 | L11: =(0.3*K12)+(0.2*J8)+(0.15*J10)+(0.25*J11)+(0.1*J13) -> 41.292857 | M11: =IF(L11<=10,1.5-0.1*L11, IF(L11<=60,0.5-0.02*(L11-10), -0.5-0.03*(L11-60))) -> -0.12585714
D12: ApoB (g/L) | E12: 1.1 | F12: =E12+(E12/100*6) -> 1.166 | G12: =F12+(F12/100*6) -> 1.23596 | H12: =G12+(G12/100*6) -> 1.3101176 | I12: =H12+(H12/100*6) -> 1.3887247 | J12: =E12*100 -> 110 | K12: =IF(J12<80,5*(J12/80), IF(J12<100,10+20*(J12-80)/20, IF(J12<130,30+25*(J12-100)/30, IF(J12<160,55+25*(J12-130)/30, IF(J12<200,80+20*(J12-160)/40,100))))) -> 38.333333
D13: hsCRP (mg/L) | E13: 3.5 | F13: =E13+(E13/100*18) -> 4.13 | G13: =F13+(F13/100*18) -> 4.8734 | H13: =G13+(G13/100*18) -> 5.750612 | I13: =H13+(H13/100*18) -> 6.7857222 | J13: =IF(E13<1,10*(E13/1), IF(E13<3,10+40*(E13-1)/2, 50+50*(MIN(E13,10)-3)/7)) -> 53.571429
D14: Gait speed (m/s) | E14: 1.1 | F14: =E14-(E14/100*6) -> 1.034 | G14: =F14+(F14/100*6) -> 1.09604 | H14: =G14+(G14/100*7) -> 1.1727628 | I14: =H14+(H14/100*7) -> 1.2548562 | J14: =IFERROR(FORECAST(E14, OFFSET(Mobility_Normative_Data!$A$3, MATCH(E14, Mobility_Normative_Data!$B$3:$B$17, -1)-1, 0, 2), OFFSET(Mobility_Normative_Data!$B$3, MATCH(E14, Mobility_Normative_Data!$B$3:$B$17, -1)-1, 0, 2)), INDEX(Mobility_Normative_Data!$A$3:$A$17, MATCH(E14, Mobility_Normative_Data!$B$3:$B$17, -1))) -> 80
D15: Timed Up and Go (sec) | E15: 8.5 | F15: =E15+(E15/100*10) -> 9.35 | G15: =F15+(F15/100*10) -> 10.285 | H15: =G15+(G15/100*10) -> 11.3135 | I15: =H15+(H15/100*10) -> 12.44485 | J15: =FORECAST(E15, OFFSET(Mobility_Normative_Data!$E$3, MATCH(E15, Mobility_Normative_Data!$F$3:$F$18, 1)-1, 0, 2), OFFSET(Mobility_Normative_Data!$F$3, MATCH(E15, Mobility_Normative_Data!$F$3:$F$18, 1)-1, 0, 2)) -> 65
D16: Single leg stance (sec) | E16: 15 | F16: =E16-(E16/100*20) -> 12 | G16: =F16+(F16/100*20) -> 14.4 | H16: =G16+(G16/100*20) -> 17.28 | I16: =H16+(H16/100*20) -> 20.736 | J16: =FORECAST(E16, OFFSET(Mobility_Normative_Data!$I$3, MATCH(E16, Mobility_Normative_Data!$J$3:$J$17, -1)-1, 0, 2), OFFSET(Mobility_Normative_Data!$J$3, MATCH(E16, Mobility_Normative_Data!$J$3:$J$17, -1)-1, 0, 2)) -> 75
D17: Sit and reach (cm) | E17: 36 | F17: =E17-(E17/100*10) -> 32.4 | G17: =F17+(F17/100*10) -> 35.64 | H17: =G17+(G17/100*10) -> 39.204 | I17: =H17+(H17/100*10) -> 43.1244 | J17: =FORECAST(E17, OFFSET(Mobility_Normative_Data!$M$3, MATCH(E17, Mobility_Normative_Data!$N$3:$N$17, -1)-1, 0, 2), OFFSET(Mobility_Normative_Data!$N$3, MATCH(E17, Mobility_Normative_Data!$N$3:$N$17, -1)-1, 0, 2)) -> 35
D18: Processing speed (SD) | E18: 2.5 | F18: =E18 +(-0.2) -> 2.3 | G18: =F18 +(-0.2) -> 2.1 | H18: =G18 +(-0.3) -> 1.8 | I18: =H18 +(-0.3) -> 1.5 | J18: =MAX(18,B27-(E18*25)) -> 18
D19: Working memory (SD) | E19: 1.5 | F19: =E19+(-0.2) -> 1.3 | G19: =F19 +(-0.2) -> 1.1 | H19: =G19 +(-0.3) -> 0.8 | I19: =H19 +(-0.3) -> 0.5 | J19: =MAX(18,B27-(E19*35)) -> 18
A23: Overall Decline predicitons
B25: Present | C25: 10 years time | D25: 20 Years time | E25: Thirty years | F25: 40 years
A26: Sex | B26: Male
A27: Chronological | B27: =B2 -> 24 | C27: =B27+10 -> 34 | D27: =C27+10 -> 44 | E27: =D27+10 -> 54 | F27: =E27+10 -> 64
A28: Vitality | B28: =M2 -> 52.391667 | C28: =B28+(B28/100*11.5) -> 58.416708 | D28: =C28+(C28/100*32.2) -> 77.226888 | E28: =D28+(D28/100*32.2) -> 102.09395 | F28: =E28+(E28/100*32.2) -> 134.9682
A29: Strength | B29: =M3 -> 78.928571 | C29: =B29+(B29/100*12.3) -> 88.636786 | D29: =C29+(C29/100*30.8) -> 115.93692 | E29: =D29+(D29/100*30.8) -> 151.64549 | F29: =E29+(E29/100*30.8) -> 198.3523
A30: Metabolic | B30: =M4 -> 25.132714 | C30: =B30+(B30/100*5.5) -> 26.515014 | D30: =C30+(C30/100*11) -> 29.431665 | E30: =D30+(D30/100*11) -> 32.669148 | F30: =E30+(E30/100*11) -> 36.262755
A31: Mobility | B31: =M5 -> 68 | C31: =B31+(B31/100*9.9) -> 74.732 | D31: =C31+(C31/100*19.8) -> 89.528936 | E31: =D31+(D31/100*19.8) -> 107.25567 | F31: =E31+(E31/100*19.8) -> 128.49229
A32: Cognitive | B32: =M6 -> 18 | C32: =B32+(B32/100*20) -> 21.6 | D32: =C32+(C32/100*60) -> 34.56 | E32: =D32+(D32/100*60) -> 55.296 | F32: =E32+(E32/100*60) -> 88.4736
A36: Functional Biological Age
A37: =(B28/100*20)+(B29/100*20)+(B30/100*25)+(B31/100*20)+(B32/100*15) -> 48.847226
B42: Age | C42: Vitality | D42: Age | E42: Strength | F42: Age | G42: Metabolic | H42: Age | I42: Mobility | J42: Age | K42: Cognitive
B43: =B27 -> 24 | C43: =B28 -> 52.391667 | D43: =B43 -> 24 | E43: =B29 -> 78.928571 | F43: =B27 -> 24 | G43: =B30 -> 25.132714 | H43: =B27 -> 24 | I43: =B31 -> 68 | J43: =B27 -> 24 | K43: =B32 -> 18
B44: =C27 -> 34 | C44: =C28 -> 58.416708 | D44: =B44 -> 34 | E44: =C29 -> 88.636786 | F44: =C27 -> 34 | G44: =C30 -> 26.515014 | H44: =C27 -> 34 | I44: =C31 -> 74.732 | J44: =C27 -> 34 | K44: =C32 -> 21.6
B45: =D27 -> 44 | C45: =D28 -> 77.226888 | D45: =D27 -> 44 | E45: =D29 -> 115.93692 | F45: =D27 -> 44 | G45: =D30 -> 29.431665 | H45: =D27 -> 44 | I45: =D31 -> 89.528936 | J45: =D27 -> 44 | K45: =D32 -> 34.56
B46: =E27 -> 54 | C46: =E28 -> 102.09395 | D46: =E27 -> 54 | E46: =E29 -> 151.64549 | F46: =E27 -> 54 | G46: =E30 -> 32.669148 | H46: =E27 -> 54 | I46: =E31 -> 107.25567 | J46: =E27 -> 54 | K46: =E32 -> 55.296
B47: =F27 -> 64 | C47: =F28 -> 134.9682 | D47: =F27 -> 64 | E47: =F29 -> 198.3523 | F47: =F27 -> 64 | G47: =F31 -> 128.49229 | H47: =F27 -> 64 | I47: =F31 -> 128.49229 | J47: =F27 -> 64 | K47: =F32 -> 88.4736
P49: Graphing
P50: Chronological Age | Q50: Vitality Decline | S50: Chronological Age | T50: Strength Decline | V50: Chronological Age | W50: Metabolic Decline | Y50: Chronological Age | Z50: Mobility Decline | AB50: Chronological Age | AC50: Cognitive Decline
P51: =B27 -> 24 | Q51: =B28 -> 52.391667 | S51: =P51 -> 24 | T51: =B29 -> 78.928571 | V51: =P51 -> 24 | W51: =B30 -> 25.132714 | Y51: =P51 -> 24 | Z51: =B31 -> 68 | AB51: =P51 -> 24 | AC51: =B32 -> 18
P52: =P51+1 -> 25 | Q52: =Q51+(Q51*0.0115) -> 52.994171 | S52: =S51+1 -> 25 | T52: =T51+(T51*0.0123) -> 79.899393 | V52: =V51+1 -> 25 | W52: =W51+(W51*0.011) -> 25.409174 | Y52: =Y51+1 -> 25 | Z52: =Z51+(Z51*0.0099) -> 68.6732 | AB52: =AB51+1 -> 25 | AC52: =AC51+(AC51*0.02) -> 18.36
...

Sheet Persona_4
A1: Persona | B1: Arthur | D1: Metric | F1: 10 Years (49) | G1: 20 Years (59) | H1: 30 Years (69) | I1: 40 Years (79) | M1: Combined Scores
A2: Age | B2: 61 | D2: VO2 max (ml/kg/min) | E2: 24 | F2: =E2+(E2/100*10) -> 26.4 | G2: =F2+(F2/100*10) -> 29.04 | H2: =G2+(G2/100*10) -> 31.944 | I2: =H2+(H2/100*15) -> 36.7356 | L2: Vitality | M2: =B27+ ((1 -((E2 / 30.2) * 0.7 )-((E3/ 100) * 0.3 )) *100) -> 78.370861
A3: Detail | B3: Arthur worked in construction his whole life and still lifts heavy weights in his garage. He eats a high-meat diet and ignores cardio, prioritizing raw strength to "stay useful" around the house. | D3: FEV1 (% predicted) | E3: 90 | F3: =E3-(E3/100*10) -> 81 | G3: =F3-(F3/100*10) -> 72.9 | H3: =G3-(G3/100*15) -> 61.965 | I3: =H3-(H3/100*15) -> 52.67025 | L3: Strength | M3: =((J4/100*50)+(J5/100*25)+(J6/100*25)) -> 48.125 | O3: Functional Biological Age
